2016-10-08 06:18:10,062 [Thread-2:140378053277440] [django.request:124] [exception:handle_uncaught_exception] [ERROR]- Internal Server Error: /
Traceback (most recent call last):
  File "/home/lgy/project/dj/env_2.7/local/lib/python2.7/site-packages/django/core/handlers/exception.py", line 39, in inner
    response = get_response(request)
  File "/home/lgy/project/dj/env_2.7/local/lib/python2.7/site-packages/django/core/handlers/base.py", line 187, in _get_response
    response = self.process_exception_by_middleware(e, request)
  File "/home/lgy/project/dj/env_2.7/local/lib/python2.7/site-packages/django/core/handlers/base.py", line 185, in _get_response
    response = wrapped_callback(request, *callback_args, **callback_kwargs)
  File "/home/lgy/project/dj/blog_project/blog/views.py", line 23, in home
    return render(request,"index.html",locals())
  File "/home/lgy/project/dj/env_2.7/local/lib/python2.7/site-packages/django/shortcuts.py", line 30, in render
    content = loader.render_to_string(template_name, context, request, using=using)
  File "/home/lgy/project/dj/env_2.7/local/lib/python2.7/site-packages/django/template/loader.py", line 68, in render_to_string
    return template.render(context, request)
  File "/home/lgy/project/dj/env_2.7/local/lib/python2.7/site-packages/django/template/backends/django.py", line 66, in render
    return self.template.render(context)
  File "/home/lgy/project/dj/env_2.7/local/lib/python2.7/site-packages/django/template/base.py", line 206, in render
    with context.bind_template(self):
  File "/usr/lib/python2.7/contextlib.py", line 17, in __enter__
    return self.gen.next()
  File "/home/lgy/project/dj/env_2.7/local/lib/python2.7/site-packages/django/template/context.py", line 232, in bind_template
    processors = (template.engine.template_context_processors +
  File "/home/lgy/project/dj/env_2.7/local/lib/python2.7/site-packages/django/utils/functional.py", line 35, in __get__
    res = instance.__dict__[self.name] = self.func(instance)
  File "/home/lgy/project/dj/env_2.7/local/lib/python2.7/site-packages/django/template/engine.py", line 91, in template_context_processors
    return tuple(import_string(path) for path in context_processors)
  File "/home/lgy/project/dj/env_2.7/local/lib/python2.7/site-packages/django/template/engine.py", line 91, in <genexpr>
    return tuple(import_string(path) for path in context_processors)
  File "/home/lgy/project/dj/env_2.7/local/lib/python2.7/site-packages/django/utils/module_loading.py", line 27, in import_string
    six.reraise(ImportError, ImportError(msg), sys.exc_info()[2])
  File "/home/lgy/project/dj/env_2.7/local/lib/python2.7/site-packages/django/utils/module_loading.py", line 23, in import_string
    return getattr(module, class_name)
ImportError: Module "blog.views" does not define a "gloal_settings" attribute/class
2016-10-08 12:24:03,807 [Thread-3:140235537086208] [django.request:152] [base:get_response] [WARNING]- Not Found: /favicon.ico
2016-10-08 15:00:01,822 [Thread-11:140349630400256] [django.request:152] [base:get_response] [WARNING]- Not Found: /favicon.ico
2016-10-09 08:11:28,893 [Thread-8:140163116439296] [django.request:124] [exception:handle_uncaught_exception] [ERROR]- Internal Server Error: /admin/upload/kindeditor
Traceback (most recent call last):
  File "/home/lgy/project/dj/env_2.7/local/lib/python2.7/site-packages/django/core/handlers/exception.py", line 39, in inner
    response = get_response(request)
  File "/home/lgy/project/dj/env_2.7/local/lib/python2.7/site-packages/django/core/handlers/base.py", line 187, in _get_response
    response = self.process_exception_by_middleware(e, request)
  File "/home/lgy/project/dj/env_2.7/local/lib/python2.7/site-packages/django/core/handlers/base.py", line 185, in _get_response
    response = wrapped_callback(request, *callback_args, **callback_kwargs)
  File "/home/lgy/project/dj/env_2.7/local/lib/python2.7/site-packages/django/views/decorators/csrf.py", line 58, in wrapped_view
    return view_func(*args, **kwargs)
  File "/home/lgy/project/dj/blog_project/blog/upload.py", line 27, in upload_image
    result =upload_file_cdn(files, dir_name)
  File "/home/lgy/project/dj/blog_project/blog/upload.py", line 66, in upload_file_cdn
    request = qcloud_cos.UploadFileRequest(bucket_name=bucket,cos_path='/lgy.jpg',local_path=files.file)
  File "/home/lgy/project/dj/env_2.7/local/lib/python2.7/site-packages/qcloud_cos/cos_request.py", line 90, in __init__
    self._local_path          = local_path.strip()
AttributeError: '_io.BytesIO' object has no attribute 'strip'
2016-10-09 08:39:01,445 [Thread-27:140673505019648] [django.request:124] [exception:handle_uncaught_exception] [ERROR]- Internal Server Error: /admin/upload/kindeditor
Traceback (most recent call last):
  File "/home/lgy/project/dj/env_2.7/local/lib/python2.7/site-packages/django/core/handlers/exception.py", line 39, in inner
    response = get_response(request)
  File "/home/lgy/project/dj/env_2.7/local/lib/python2.7/site-packages/django/core/handlers/base.py", line 187, in _get_response
    response = self.process_exception_by_middleware(e, request)
  File "/home/lgy/project/dj/env_2.7/local/lib/python2.7/site-packages/django/core/handlers/base.py", line 185, in _get_response
    response = wrapped_callback(request, *callback_args, **callback_kwargs)
  File "/home/lgy/project/dj/env_2.7/local/lib/python2.7/site-packages/django/views/decorators/csrf.py", line 58, in wrapped_view
    return view_func(*args, **kwargs)
  File "/home/lgy/project/dj/blog_project/blog/upload.py", line 27, in upload_image
    result =upload_file_cdn(files, dir_name)
  File "/home/lgy/project/dj/blog_project/blog/upload.py", line 72, in upload_file_cdn
    multi_effect_signature = auth_obj.sign_more(bucket=bucket, cos_path='/kindeditor/', expired= int(time()) + 600 )
  File "/home/lgy/project/dj/env_2.7/local/lib/python2.7/site-packages/qcloud_cos/cos_auth.py", line 51, in sign_more
    return self.app_sign(bucket, cos_path, expired)
  File "/home/lgy/project/dj/env_2.7/local/lib/python2.7/site-packages/qcloud_cos/cos_auth.py", line 35, in app_sign
    sign_hex    = hmac_digest + plain_text
UnicodeDecodeError: 'ascii' codec can't decode byte 0xca in position 0: ordinal not in range(128)
2016-10-09 08:41:29,317 [Thread-28:140673505019648] [django.request:124] [exception:handle_uncaught_exception] [ERROR]- Internal Server Error: /admin/upload/kindeditor
Traceback (most recent call last):
  File "/home/lgy/project/dj/env_2.7/local/lib/python2.7/site-packages/django/core/handlers/exception.py", line 39, in inner
    response = get_response(request)
  File "/home/lgy/project/dj/env_2.7/local/lib/python2.7/site-packages/django/core/handlers/base.py", line 187, in _get_response
    response = self.process_exception_by_middleware(e, request)
  File "/home/lgy/project/dj/env_2.7/local/lib/python2.7/site-packages/django/core/handlers/base.py", line 185, in _get_response
    response = wrapped_callback(request, *callback_args, **callback_kwargs)
  File "/home/lgy/project/dj/env_2.7/local/lib/python2.7/site-packages/django/views/decorators/csrf.py", line 58, in wrapped_view
    return view_func(*args, **kwargs)
  File "/home/lgy/project/dj/blog_project/blog/upload.py", line 27, in upload_image
    result =upload_file_cdn(files, dir_name)
  File "/home/lgy/project/dj/blog_project/blog/upload.py", line 72, in upload_file_cdn
    multi_effect_signature = auth_obj.sign_more(bucket=bucket, cos_path='/kindeditor/', expired= int(time()) + 600 )
  File "/home/lgy/project/dj/env_2.7/local/lib/python2.7/site-packages/qcloud_cos/cos_auth.py", line 51, in sign_more
    return self.app_sign(bucket, cos_path, expired)
  File "/home/lgy/project/dj/env_2.7/local/lib/python2.7/site-packages/qcloud_cos/cos_auth.py", line 35, in app_sign
    sign_hex    = hmac_digest + plain_text
UnicodeDecodeError: 'ascii' codec can't decode byte 0xb5 in position 0: ordinal not in range(128)
2016-10-09 08:42:50,925 [Thread-2:140129383032576] [django.request:124] [exception:handle_uncaught_exception] [ERROR]- Internal Server Error: /admin/upload/kindeditor
Traceback (most recent call last):
  File "/home/lgy/project/dj/env_2.7/local/lib/python2.7/site-packages/django/core/handlers/exception.py", line 39, in inner
    response = get_response(request)
  File "/home/lgy/project/dj/env_2.7/local/lib/python2.7/site-packages/django/core/handlers/base.py", line 187, in _get_response
    response = self.process_exception_by_middleware(e, request)
  File "/home/lgy/project/dj/env_2.7/local/lib/python2.7/site-packages/django/core/handlers/base.py", line 185, in _get_response
    response = wrapped_callback(request, *callback_args, **callback_kwargs)
  File "/home/lgy/project/dj/env_2.7/local/lib/python2.7/site-packages/django/views/decorators/csrf.py", line 58, in wrapped_view
    return view_func(*args, **kwargs)
  File "/home/lgy/project/dj/blog_project/blog/upload.py", line 27, in upload_image
    result =upload_file_cdn(files, dir_name)
  File "/home/lgy/project/dj/blog_project/blog/upload.py", line 72, in upload_file_cdn
    multi_effect_signature = auth_obj.sign_more(bucket=bucket, cos_path=u'/kindeditor/', expired= int(time()) + 600 )
  File "/home/lgy/project/dj/env_2.7/local/lib/python2.7/site-packages/qcloud_cos/cos_auth.py", line 51, in sign_more
    return self.app_sign(bucket, cos_path, expired)
  File "/home/lgy/project/dj/env_2.7/local/lib/python2.7/site-packages/qcloud_cos/cos_auth.py", line 35, in app_sign
    sign_hex    = hmac_digest + plain_text
UnicodeDecodeError: 'ascii' codec can't decode byte 0xe3 in position 2: ordinal not in range(128)
2016-10-09 08:43:10,497 [Thread-28:140129003890432] [django.request:124] [exception:handle_uncaught_exception] [ERROR]- Internal Server Error: /admin/upload/kindeditor
Traceback (most recent call last):
  File "/home/lgy/project/dj/env_2.7/local/lib/python2.7/site-packages/django/core/handlers/exception.py", line 39, in inner
    response = get_response(request)
  File "/home/lgy/project/dj/env_2.7/local/lib/python2.7/site-packages/django/core/handlers/base.py", line 187, in _get_response
    response = self.process_exception_by_middleware(e, request)
  File "/home/lgy/project/dj/env_2.7/local/lib/python2.7/site-packages/django/core/handlers/base.py", line 185, in _get_response
    response = wrapped_callback(request, *callback_args, **callback_kwargs)
  File "/home/lgy/project/dj/env_2.7/local/lib/python2.7/site-packages/django/views/decorators/csrf.py", line 58, in wrapped_view
    return view_func(*args, **kwargs)
  File "/home/lgy/project/dj/blog_project/blog/upload.py", line 27, in upload_image
    result =upload_file_cdn(files, dir_name)
  File "/home/lgy/project/dj/blog_project/blog/upload.py", line 72, in upload_file_cdn
    multi_effect_signature = auth_obj.sign_more(bucket=bucket, cos_path=u'/kindeditor/', expired= int(time()) + 600 )
  File "/home/lgy/project/dj/env_2.7/local/lib/python2.7/site-packages/qcloud_cos/cos_auth.py", line 51, in sign_more
    return self.app_sign(bucket, cos_path, expired)
  File "/home/lgy/project/dj/env_2.7/local/lib/python2.7/site-packages/qcloud_cos/cos_auth.py", line 35, in app_sign
    sign_hex    = hmac_digest + plain_text
UnicodeDecodeError: 'ascii' codec can't decode byte 0x87 in position 2: ordinal not in range(128)
2016-10-09 08:47:14,693 [Thread-4:140590207633152] [django.request:124] [exception:handle_uncaught_exception] [ERROR]- Internal Server Error: /admin/upload/kindeditor
Traceback (most recent call last):
  File "/home/lgy/project/dj/env_2.7/local/lib/python2.7/site-packages/django/core/handlers/exception.py", line 39, in inner
    response = get_response(request)
  File "/home/lgy/project/dj/env_2.7/local/lib/python2.7/site-packages/django/core/handlers/base.py", line 187, in _get_response
    response = self.process_exception_by_middleware(e, request)
  File "/home/lgy/project/dj/env_2.7/local/lib/python2.7/site-packages/django/core/handlers/base.py", line 185, in _get_response
    response = wrapped_callback(request, *callback_args, **callback_kwargs)
  File "/home/lgy/project/dj/env_2.7/local/lib/python2.7/site-packages/django/views/decorators/csrf.py", line 58, in wrapped_view
    return view_func(*args, **kwargs)
  File "/home/lgy/project/dj/blog_project/blog/upload.py", line 27, in upload_image
    result =upload_file_cdn(files, dir_name)
  File "/home/lgy/project/dj/blog_project/blog/upload.py", line 62, in upload_file_cdn
    file_url = cdn_url + APP_ID + '/' + Bucket_name + '/' + dir_name + '/' + files.name
TypeError: coercing to Unicode: need string or buffer, int found
2016-10-09 09:20:39,047 [Thread-27:140061861406464] [django.request:124] [exception:handle_uncaught_exception] [ERROR]- Internal Server Error: /admin/upload/kindeditor
Traceback (most recent call last):
  File "/home/lgy/project/dj/env_2.7/local/lib/python2.7/site-packages/django/core/handlers/exception.py", line 39, in inner
    response = get_response(request)
  File "/home/lgy/project/dj/env_2.7/local/lib/python2.7/site-packages/django/core/handlers/base.py", line 187, in _get_response
    response = self.process_exception_by_middleware(e, request)
  File "/home/lgy/project/dj/env_2.7/local/lib/python2.7/site-packages/django/core/handlers/base.py", line 185, in _get_response
    response = wrapped_callback(request, *callback_args, **callback_kwargs)
  File "/home/lgy/project/dj/env_2.7/local/lib/python2.7/site-packages/django/views/decorators/csrf.py", line 58, in wrapped_view
    return view_func(*args, **kwargs)
  File "/home/lgy/project/dj/blog_project/blog/upload.py", line 27, in upload_image
    result =upload_file_cdn(files, dir_name)
  File "/home/lgy/project/dj/blog_project/blog/upload.py", line 90, in upload_file_cdn
    print r.content
NameError: global name 'r' is not defined
2016-10-09 10:00:26,835 [Thread-4:139781742737152] [django.request:152] [base:get_response] [WARNING]- Not Found: /uploads/kindeditor/2016/10/4e948a62-8d6a-11e6-bd56-54ee7574e650.png
2016-10-09 10:00:33,818 [Thread-5:139781734344448] [django.request:124] [exception:handle_uncaught_exception] [ERROR]- Internal Server Error: /admin/upload/kindeditor
Traceback (most recent call last):
  File "/home/lgy/project/dj/env_2.7/local/lib/python2.7/site-packages/django/core/handlers/exception.py", line 39, in inner
    response = get_response(request)
  File "/home/lgy/project/dj/env_2.7/local/lib/python2.7/site-packages/django/core/handlers/base.py", line 187, in _get_response
    response = self.process_exception_by_middleware(e, request)
  File "/home/lgy/project/dj/env_2.7/local/lib/python2.7/site-packages/django/core/handlers/base.py", line 185, in _get_response
    response = wrapped_callback(request, *callback_args, **callback_kwargs)
  File "/home/lgy/project/dj/env_2.7/local/lib/python2.7/site-packages/django/views/decorators/csrf.py", line 58, in wrapped_view
    return view_func(*args, **kwargs)
  File "/home/lgy/project/dj/blog_project/blog/upload.py", line 27, in upload_image
    result =upload_file_cdn(files, dir_name)
  File "/home/lgy/project/dj/blog_project/blog/upload.py", line 79, in upload_file_cdn
    print files.file.size
AttributeError: '_io.BytesIO' object has no attribute 'size'
2016-10-09 10:01:41,196 [Thread-4:139667034863360] [django.request:152] [base:get_response] [WARNING]- Not Found: /uploads/kindeditor/2016/10/4e948a62-8d6a-11e6-bd56-54ee7574e650.png
2016-10-09 10:01:47,628 [Thread-5:139667026470656] [django.request:124] [exception:handle_uncaught_exception] [ERROR]- Internal Server Error: /admin/upload/kindeditor
Traceback (most recent call last):
  File "/home/lgy/project/dj/env_2.7/local/lib/python2.7/site-packages/django/core/handlers/exception.py", line 39, in inner
    response = get_response(request)
  File "/home/lgy/project/dj/env_2.7/local/lib/python2.7/site-packages/django/core/handlers/base.py", line 187, in _get_response
    response = self.process_exception_by_middleware(e, request)
  File "/home/lgy/project/dj/env_2.7/local/lib/python2.7/site-packages/django/core/handlers/base.py", line 185, in _get_response
    response = wrapped_callback(request, *callback_args, **callback_kwargs)
  File "/home/lgy/project/dj/env_2.7/local/lib/python2.7/site-packages/django/views/decorators/csrf.py", line 58, in wrapped_view
    return view_func(*args, **kwargs)
  File "/home/lgy/project/dj/blog_project/blog/upload.py", line 27, in upload_image
    result =upload_file_cdn(files, dir_name)
  File "/home/lgy/project/dj/blog_project/blog/upload.py", line 86, in upload_file_cdn
    "Content-Length":files.file.size
AttributeError: '_io.BytesIO' object has no attribute 'size'
2016-10-09 10:04:01,272 [Thread-4:140687760684800] [django.request:152] [base:get_response] [WARNING]- Not Found: /uploads/kindeditor/2016/10/4e948a62-8d6a-11e6-bd56-54ee7574e650.png
2016-10-09 10:04:07,865 [Thread-5:140687752292096] [django.request:124] [exception:handle_uncaught_exception] [ERROR]- Internal Server Error: /admin/upload/kindeditor
Traceback (most recent call last):
  File "/home/lgy/project/dj/env_2.7/local/lib/python2.7/site-packages/django/core/handlers/exception.py", line 39, in inner
    response = get_response(request)
  File "/home/lgy/project/dj/env_2.7/local/lib/python2.7/site-packages/django/core/handlers/base.py", line 187, in _get_response
    response = self.process_exception_by_middleware(e, request)
  File "/home/lgy/project/dj/env_2.7/local/lib/python2.7/site-packages/django/core/handlers/base.py", line 185, in _get_response
    response = wrapped_callback(request, *callback_args, **callback_kwargs)
  File "/home/lgy/project/dj/env_2.7/local/lib/python2.7/site-packages/django/views/decorators/csrf.py", line 58, in wrapped_view
    return view_func(*args, **kwargs)
  File "/home/lgy/project/dj/blog_project/blog/upload.py", line 28, in upload_image
    result =upload_file_cdn(files, dir_name)
  File "/home/lgy/project/dj/blog_project/blog/upload.py", line 87, in upload_file_cdn
    "Content-Length":files.file.size
AttributeError: '_io.BytesIO' object has no attribute 'size'
2016-10-09 10:05:19,538 [Thread-4:139741701187328] [django.request:152] [base:get_response] [WARNING]- Not Found: /uploads/kindeditor/2016/10/4e948a62-8d6a-11e6-bd56-54ee7574e650.png
2016-10-09 10:05:25,729 [Thread-5:139741692794624] [django.request:124] [exception:handle_uncaught_exception] [ERROR]- Internal Server Error: /admin/upload/kindeditor
Traceback (most recent call last):
  File "/home/lgy/project/dj/env_2.7/local/lib/python2.7/site-packages/django/core/handlers/exception.py", line 39, in inner
    response = get_response(request)
  File "/home/lgy/project/dj/env_2.7/local/lib/python2.7/site-packages/django/core/handlers/base.py", line 187, in _get_response
    response = self.process_exception_by_middleware(e, request)
  File "/home/lgy/project/dj/env_2.7/local/lib/python2.7/site-packages/django/core/handlers/base.py", line 185, in _get_response
    response = wrapped_callback(request, *callback_args, **callback_kwargs)
  File "/home/lgy/project/dj/env_2.7/local/lib/python2.7/site-packages/django/views/decorators/csrf.py", line 58, in wrapped_view
    return view_func(*args, **kwargs)
  File "/home/lgy/project/dj/blog_project/blog/upload.py", line 28, in upload_image
    result =upload_file_cdn(files, dir_name,file_size)
  File "/home/lgy/project/dj/blog_project/blog/upload.py", line 92, in upload_file_cdn
    r = requests.post(url=file_url, headers= headers, data=data)
  File "/home/lgy/project/dj/env_2.7/local/lib/python2.7/site-packages/requests/api.py", line 110, in post
    return request('post', url, data=data, json=json, **kwargs)
  File "/home/lgy/project/dj/env_2.7/local/lib/python2.7/site-packages/requests/api.py", line 56, in request
    return session.request(method=method, url=url, **kwargs)
  File "/home/lgy/project/dj/env_2.7/local/lib/python2.7/site-packages/requests/sessions.py", line 461, in request
    prep = self.prepare_request(req)
  File "/home/lgy/project/dj/env_2.7/local/lib/python2.7/site-packages/requests/sessions.py", line 394, in prepare_request
    hooks=merge_hooks(request.hooks, self.hooks),
  File "/home/lgy/project/dj/env_2.7/local/lib/python2.7/site-packages/requests/models.py", line 295, in prepare
    self.prepare_headers(headers)
  File "/home/lgy/project/dj/env_2.7/local/lib/python2.7/site-packages/requests/models.py", line 409, in prepare_headers
    check_header_validity(header)
  File "/home/lgy/project/dj/env_2.7/local/lib/python2.7/site-packages/requests/utils.py", line 800, in check_header_validity
    "not %s" % (value, type(value)))
InvalidHeader: Header value 96520 must be of type str or bytes, not <type 'int'>
2016-10-09 10:07:26,142 [Thread-27:140068916279040] [django.request:152] [base:get_response] [WARNING]- Not Found: /uploads/kindeditor/2016/10/4e948a62-8d6a-11e6-bd56-54ee7574e650.png
2016-10-09 10:09:57,634 [Thread-4:140704596616960] [django.request:152] [base:get_response] [WARNING]- Not Found: /uploads/kindeditor/2016/10/4e948a62-8d6a-11e6-bd56-54ee7574e650.png
2016-10-09 10:10:04,342 [Thread-5:140704588224256] [django.request:124] [exception:handle_uncaught_exception] [ERROR]- Internal Server Error: /admin/upload/kindeditor
Traceback (most recent call last):
  File "/home/lgy/project/dj/env_2.7/local/lib/python2.7/site-packages/django/core/handlers/exception.py", line 39, in inner
    response = get_response(request)
  File "/home/lgy/project/dj/env_2.7/local/lib/python2.7/site-packages/django/core/handlers/base.py", line 187, in _get_response
    response = self.process_exception_by_middleware(e, request)
  File "/home/lgy/project/dj/env_2.7/local/lib/python2.7/site-packages/django/core/handlers/base.py", line 185, in _get_response
    response = wrapped_callback(request, *callback_args, **callback_kwargs)
  File "/home/lgy/project/dj/env_2.7/local/lib/python2.7/site-packages/django/views/decorators/csrf.py", line 58, in wrapped_view
    return view_func(*args, **kwargs)
  File "/home/lgy/project/dj/blog_project/blog/upload.py", line 28, in upload_image
    result =upload_file_cdn(files, dir_name,file_size)
  File "/home/lgy/project/dj/blog_project/blog/upload.py", line 92, in upload_file_cdn
    r = requests.post(url=file_url, headers= headers, data=data)
  File "/home/lgy/project/dj/env_2.7/local/lib/python2.7/site-packages/requests/api.py", line 110, in post
    return request('post', url, data=data, json=json, **kwargs)
  File "/home/lgy/project/dj/env_2.7/local/lib/python2.7/site-packages/requests/api.py", line 56, in request
    return session.request(method=method, url=url, **kwargs)
  File "/home/lgy/project/dj/env_2.7/local/lib/python2.7/site-packages/requests/sessions.py", line 461, in request
    prep = self.prepare_request(req)
  File "/home/lgy/project/dj/env_2.7/local/lib/python2.7/site-packages/requests/sessions.py", line 394, in prepare_request
    hooks=merge_hooks(request.hooks, self.hooks),
  File "/home/lgy/project/dj/env_2.7/local/lib/python2.7/site-packages/requests/models.py", line 295, in prepare
    self.prepare_headers(headers)
  File "/home/lgy/project/dj/env_2.7/local/lib/python2.7/site-packages/requests/models.py", line 409, in prepare_headers
    check_header_validity(header)
  File "/home/lgy/project/dj/env_2.7/local/lib/python2.7/site-packages/requests/utils.py", line 800, in check_header_validity
    "not %s" % (value, type(value)))
InvalidHeader: Header value 36422 must be of type str or bytes, not <type 'int'>
2016-10-09 14:55:50,008 [Thread-26:140483665843968] [django.request:152] [base:get_response] [WARNING]- Not Found: /uploads/kindeditor/2016/10/4e948a62-8d6a-11e6-bd56-54ee7574e650.png
2016-10-10 03:26:53,438 [Thread-50:140629979952896] [django.request:152] [base:get_response] [WARNING]- Not Found: /uploads/kindeditor/2016/10/4e948a62-8d6a-11e6-bd56-54ee7574e650.png
2016-10-10 03:27:12,813 [Thread-59:140630208710400] [django.request:152] [base:get_response] [WARNING]- Not Found: /uploads/kindeditor/2016/10/4e948a62-8d6a-11e6-bd56-54ee7574e650.png
2016-10-10 03:27:35,524 [Thread-70:140630191924992] [django.request:152] [base:get_response] [WARNING]- Not Found: /uploads/kindeditor/2016/10/4e948a62-8d6a-11e6-bd56-54ee7574e650.png
2016-10-10 11:24:47,271 [Thread-2:140138252998400] [django.request:124] [exception:handle_uncaught_exception] [ERROR]- Internal Server Error: /
Traceback (most recent call last):
  File "/home/lgy/project/dj/env_2.7/local/lib/python2.7/site-packages/django/core/handlers/exception.py", line 39, in inner
    response = get_response(request)
  File "/home/lgy/project/dj/env_2.7/local/lib/python2.7/site-packages/django/core/handlers/base.py", line 187, in _get_response
    response = self.process_exception_by_middleware(e, request)
  File "/home/lgy/project/dj/env_2.7/local/lib/python2.7/site-packages/django/core/handlers/base.py", line 185, in _get_response
    response = wrapped_callback(request, *callback_args, **callback_kwargs)
  File "/home/lgy/project/dj/blog_project/blog/views.py", line 48, in home
    return render(request,"index.html",locals())
  File "/home/lgy/project/dj/env_2.7/local/lib/python2.7/site-packages/django/shortcuts.py", line 30, in render
    content = loader.render_to_string(template_name, context, request, using=using)
  File "/home/lgy/project/dj/env_2.7/local/lib/python2.7/site-packages/django/template/loader.py", line 68, in render_to_string
    return template.render(context, request)
  File "/home/lgy/project/dj/env_2.7/local/lib/python2.7/site-packages/django/template/backends/django.py", line 66, in render
    return self.template.render(context)
  File "/home/lgy/project/dj/env_2.7/local/lib/python2.7/site-packages/django/template/base.py", line 208, in render
    return self._render(context)
  File "/home/lgy/project/dj/env_2.7/local/lib/python2.7/site-packages/django/template/base.py", line 199, in _render
    return self.nodelist.render(context)
  File "/home/lgy/project/dj/env_2.7/local/lib/python2.7/site-packages/django/template/base.py", line 994, in render
    bit = node.render_annotated(context)
  File "/home/lgy/project/dj/env_2.7/local/lib/python2.7/site-packages/django/template/base.py", line 961, in render_annotated
    return self.render(context)
  File "/home/lgy/project/dj/env_2.7/local/lib/python2.7/site-packages/django/template/loader_tags.py", line 174, in render
    return compiled_parent._render(context)
  File "/home/lgy/project/dj/env_2.7/local/lib/python2.7/site-packages/django/template/base.py", line 199, in _render
    return self.nodelist.render(context)
  File "/home/lgy/project/dj/env_2.7/local/lib/python2.7/site-packages/django/template/base.py", line 994, in render
    bit = node.render_annotated(context)
  File "/home/lgy/project/dj/env_2.7/local/lib/python2.7/site-packages/django/template/base.py", line 961, in render_annotated
    return self.render(context)
  File "/home/lgy/project/dj/env_2.7/local/lib/python2.7/site-packages/django/template/defaulttags.py", line 209, in render
    nodelist.append(node.render_annotated(context))
  File "/home/lgy/project/dj/env_2.7/local/lib/python2.7/site-packages/django/template/base.py", line 961, in render_annotated
    return self.render(context)
  File "/home/lgy/project/dj/env_2.7/local/lib/python2.7/site-packages/django/template/defaulttags.py", line 439, in render
    url = reverse(view_name, args=args, kwargs=kwargs, current_app=current_app)
  File "/home/lgy/project/dj/env_2.7/local/lib/python2.7/site-packages/django/urls/base.py", line 91, in reverse
    return force_text(iri_to_uri(resolver._reverse_with_prefix(view, prefix, *args, **kwargs)))
  File "/home/lgy/project/dj/env_2.7/local/lib/python2.7/site-packages/django/urls/resolvers.py", line 392, in _reverse_with_prefix
    (lookup_view_s, args, kwargs, len(patterns), patterns)
NoReverseMatch: Reverse for 'archive' with arguments '()' and keyword arguments '{}' not found. 0 pattern(s) tried: []
2016-10-10 11:44:50,442 [Thread-3:140671203460864] [django.request:124] [exception:handle_uncaught_exception] [ERROR]- Internal Server Error: /archive
Traceback (most recent call last):
  File "/home/lgy/project/dj/env_2.7/local/lib/python2.7/site-packages/django/core/handlers/exception.py", line 39, in inner
    response = get_response(request)
  File "/home/lgy/project/dj/env_2.7/local/lib/python2.7/site-packages/django/core/handlers/base.py", line 187, in _get_response
    response = self.process_exception_by_middleware(e, request)
  File "/home/lgy/project/dj/env_2.7/local/lib/python2.7/site-packages/django/core/handlers/base.py", line 185, in _get_response
    response = wrapped_callback(request, *callback_args, **callback_kwargs)
  File "/home/lgy/project/dj/blog_project/blog/views.py", line 77, in archive
    return render(request,"archive.html",locals())
  File "/home/lgy/project/dj/env_2.7/local/lib/python2.7/site-packages/django/shortcuts.py", line 30, in render
    content = loader.render_to_string(template_name, context, request, using=using)
  File "/home/lgy/project/dj/env_2.7/local/lib/python2.7/site-packages/django/template/loader.py", line 68, in render_to_string
    return template.render(context, request)
  File "/home/lgy/project/dj/env_2.7/local/lib/python2.7/site-packages/django/template/backends/django.py", line 66, in render
    return self.template.render(context)
  File "/home/lgy/project/dj/env_2.7/local/lib/python2.7/site-packages/django/template/base.py", line 208, in render
    return self._render(context)
  File "/home/lgy/project/dj/env_2.7/local/lib/python2.7/site-packages/django/template/base.py", line 199, in _render
    return self.nodelist.render(context)
  File "/home/lgy/project/dj/env_2.7/local/lib/python2.7/site-packages/django/template/base.py", line 994, in render
    bit = node.render_annotated(context)
  File "/home/lgy/project/dj/env_2.7/local/lib/python2.7/site-packages/django/template/base.py", line 961, in render_annotated
    return self.render(context)
  File "/home/lgy/project/dj/env_2.7/local/lib/python2.7/site-packages/django/template/loader_tags.py", line 174, in render
    return compiled_parent._render(context)
  File "/home/lgy/project/dj/env_2.7/local/lib/python2.7/site-packages/django/template/base.py", line 199, in _render
    return self.nodelist.render(context)
  File "/home/lgy/project/dj/env_2.7/local/lib/python2.7/site-packages/django/template/base.py", line 994, in render
    bit = node.render_annotated(context)
  File "/home/lgy/project/dj/env_2.7/local/lib/python2.7/site-packages/django/template/base.py", line 961, in render_annotated
    return self.render(context)
  File "/home/lgy/project/dj/env_2.7/local/lib/python2.7/site-packages/django/template/loader_tags.py", line 70, in render
    result = block.nodelist.render(context)
  File "/home/lgy/project/dj/env_2.7/local/lib/python2.7/site-packages/django/template/base.py", line 994, in render
    bit = node.render_annotated(context)
  File "/home/lgy/project/dj/env_2.7/local/lib/python2.7/site-packages/django/template/base.py", line 961, in render_annotated
    return self.render(context)
  File "/home/lgy/project/dj/env_2.7/local/lib/python2.7/site-packages/django/template/defaulttags.py", line 166, in render
    len_values = len(values)
  File "/home/lgy/project/dj/env_2.7/local/lib/python2.7/site-packages/django/db/models/query.py", line 238, in __len__
    self._fetch_all()
  File "/home/lgy/project/dj/env_2.7/local/lib/python2.7/site-packages/django/db/models/query.py", line 1087, in _fetch_all
    self._result_cache = list(self.iterator())
  File "/home/lgy/project/dj/env_2.7/local/lib/python2.7/site-packages/django/db/models/query.py", line 54, in __iter__
    results = compiler.execute_sql()
  File "/home/lgy/project/dj/env_2.7/local/lib/python2.7/site-packages/django/db/models/sql/compiler.py", line 835, in execute_sql
    cursor.execute(sql, params)
  File "/home/lgy/project/dj/env_2.7/local/lib/python2.7/site-packages/django/db/backends/utils.py", line 79, in execute
    return super(CursorDebugWrapper, self).execute(sql, params)
  File "/home/lgy/project/dj/env_2.7/local/lib/python2.7/site-packages/django/db/backends/utils.py", line 64, in execute
    return self.cursor.execute(sql, params)
  File "/home/lgy/project/dj/env_2.7/local/lib/python2.7/site-packages/django/db/utils.py", line 94, in __exit__
    six.reraise(dj_exc_type, dj_exc_value, traceback)
  File "/home/lgy/project/dj/env_2.7/local/lib/python2.7/site-packages/django/db/backends/utils.py", line 64, in execute
    return self.cursor.execute(sql, params)
  File "/home/lgy/project/dj/env_2.7/local/lib/python2.7/site-packages/django/db/backends/mysql/base.py", line 110, in execute
    return self.cursor.execute(query, args)
  File "/home/lgy/project/dj/env_2.7/local/lib/python2.7/site-packages/pymysql/cursors.py", line 166, in execute
    result = self._query(query)
  File "/home/lgy/project/dj/env_2.7/local/lib/python2.7/site-packages/pymysql/cursors.py", line 322, in _query
    conn.query(q)
  File "/home/lgy/project/dj/env_2.7/local/lib/python2.7/site-packages/pymysql/connections.py", line 835, in query
    self._affected_rows = self._read_query_result(unbuffered=unbuffered)
  File "/home/lgy/project/dj/env_2.7/local/lib/python2.7/site-packages/pymysql/connections.py", line 1019, in _read_query_result
    result.read()
  File "/home/lgy/project/dj/env_2.7/local/lib/python2.7/site-packages/pymysql/connections.py", line 1302, in read
    first_packet = self.connection._read_packet()
  File "/home/lgy/project/dj/env_2.7/local/lib/python2.7/site-packages/pymysql/connections.py", line 981, in _read_packet
    packet.check_error()
  File "/home/lgy/project/dj/env_2.7/local/lib/python2.7/site-packages/pymysql/connections.py", line 393, in check_error
    err.raise_mysql_exception(self._data)
  File "/home/lgy/project/dj/env_2.7/local/lib/python2.7/site-packages/pymysql/err.py", line 107, in raise_mysql_exception
    raise errorclass(errno, errval)
InternalError: (1271, u"Illegal mix of collations for operation 'like'")
2016-10-10 14:25:18,575 [Thread-2:140088765708032] [django.request:124] [exception:handle_uncaught_exception] [ERROR]- Internal Server Error: /
Traceback (most recent call last):
  File "/home/lgy/project/dj/env_2.7/local/lib/python2.7/site-packages/django/core/handlers/exception.py", line 39, in inner
    response = get_response(request)
  File "/home/lgy/project/dj/env_2.7/local/lib/python2.7/site-packages/django/core/handlers/base.py", line 187, in _get_response
    response = self.process_exception_by_middleware(e, request)
  File "/home/lgy/project/dj/env_2.7/local/lib/python2.7/site-packages/django/core/handlers/base.py", line 185, in _get_response
    response = wrapped_callback(request, *callback_args, **callback_kwargs)
  File "/home/lgy/project/dj/blog_project/blog/views.py", line 41, in home
    return render(request,"index.html",locals())
  File "/home/lgy/project/dj/env_2.7/local/lib/python2.7/site-packages/django/shortcuts.py", line 30, in render
    content = loader.render_to_string(template_name, context, request, using=using)
  File "/home/lgy/project/dj/env_2.7/local/lib/python2.7/site-packages/django/template/loader.py", line 68, in render_to_string
    return template.render(context, request)
  File "/home/lgy/project/dj/env_2.7/local/lib/python2.7/site-packages/django/template/backends/django.py", line 66, in render
    return self.template.render(context)
  File "/home/lgy/project/dj/env_2.7/local/lib/python2.7/site-packages/django/template/base.py", line 208, in render
    return self._render(context)
  File "/home/lgy/project/dj/env_2.7/local/lib/python2.7/site-packages/django/template/base.py", line 199, in _render
    return self.nodelist.render(context)
  File "/home/lgy/project/dj/env_2.7/local/lib/python2.7/site-packages/django/template/base.py", line 994, in render
    bit = node.render_annotated(context)
  File "/home/lgy/project/dj/env_2.7/local/lib/python2.7/site-packages/django/template/base.py", line 961, in render_annotated
    return self.render(context)
  File "/home/lgy/project/dj/env_2.7/local/lib/python2.7/site-packages/django/template/loader_tags.py", line 174, in render
    return compiled_parent._render(context)
  File "/home/lgy/project/dj/env_2.7/local/lib/python2.7/site-packages/django/template/base.py", line 199, in _render
    return self.nodelist.render(context)
  File "/home/lgy/project/dj/env_2.7/local/lib/python2.7/site-packages/django/template/base.py", line 994, in render
    bit = node.render_annotated(context)
  File "/home/lgy/project/dj/env_2.7/local/lib/python2.7/site-packages/django/template/base.py", line 961, in render_annotated
    return self.render(context)
  File "/home/lgy/project/dj/env_2.7/local/lib/python2.7/site-packages/django/template/defaulttags.py", line 209, in render
    nodelist.append(node.render_annotated(context))
  File "/home/lgy/project/dj/env_2.7/local/lib/python2.7/site-packages/django/template/base.py", line 961, in render_annotated
    return self.render(context)
  File "/home/lgy/project/dj/env_2.7/local/lib/python2.7/site-packages/django/template/defaulttags.py", line 439, in render
    url = reverse(view_name, args=args, kwargs=kwargs, current_app=current_app)
  File "/home/lgy/project/dj/env_2.7/local/lib/python2.7/site-packages/django/urls/base.py", line 91, in reverse
    return force_text(iri_to_uri(resolver._reverse_with_prefix(view, prefix, *args, **kwargs)))
  File "/home/lgy/project/dj/env_2.7/local/lib/python2.7/site-packages/django/urls/resolvers.py", line 392, in _reverse_with_prefix
    (lookup_view_s, args, kwargs, len(patterns), patterns)
NoReverseMatch: Reverse for 'category' with arguments '()' and keyword arguments '{}' not found. 0 pattern(s) tried: []
2016-10-10 14:26:22,435 [Thread-2:140353179698944] [django.request:124] [exception:handle_uncaught_exception] [ERROR]- Internal Server Error: /
Traceback (most recent call last):
  File "/home/lgy/project/dj/env_2.7/local/lib/python2.7/site-packages/django/core/handlers/exception.py", line 39, in inner
    response = get_response(request)
  File "/home/lgy/project/dj/env_2.7/local/lib/python2.7/site-packages/django/core/handlers/base.py", line 187, in _get_response
    response = self.process_exception_by_middleware(e, request)
  File "/home/lgy/project/dj/env_2.7/local/lib/python2.7/site-packages/django/core/handlers/base.py", line 185, in _get_response
    response = wrapped_callback(request, *callback_args, **callback_kwargs)
  File "/home/lgy/project/dj/blog_project/blog/views.py", line 41, in home
    return render(request,"index.html",locals())
  File "/home/lgy/project/dj/env_2.7/local/lib/python2.7/site-packages/django/shortcuts.py", line 30, in render
    content = loader.render_to_string(template_name, context, request, using=using)
  File "/home/lgy/project/dj/env_2.7/local/lib/python2.7/site-packages/django/template/loader.py", line 68, in render_to_string
    return template.render(context, request)
  File "/home/lgy/project/dj/env_2.7/local/lib/python2.7/site-packages/django/template/backends/django.py", line 66, in render
    return self.template.render(context)
  File "/home/lgy/project/dj/env_2.7/local/lib/python2.7/site-packages/django/template/base.py", line 208, in render
    return self._render(context)
  File "/home/lgy/project/dj/env_2.7/local/lib/python2.7/site-packages/django/template/base.py", line 199, in _render
    return self.nodelist.render(context)
  File "/home/lgy/project/dj/env_2.7/local/lib/python2.7/site-packages/django/template/base.py", line 994, in render
    bit = node.render_annotated(context)
  File "/home/lgy/project/dj/env_2.7/local/lib/python2.7/site-packages/django/template/base.py", line 961, in render_annotated
    return self.render(context)
  File "/home/lgy/project/dj/env_2.7/local/lib/python2.7/site-packages/django/template/loader_tags.py", line 174, in render
    return compiled_parent._render(context)
  File "/home/lgy/project/dj/env_2.7/local/lib/python2.7/site-packages/django/template/base.py", line 199, in _render
    return self.nodelist.render(context)
  File "/home/lgy/project/dj/env_2.7/local/lib/python2.7/site-packages/django/template/base.py", line 994, in render
    bit = node.render_annotated(context)
  File "/home/lgy/project/dj/env_2.7/local/lib/python2.7/site-packages/django/template/base.py", line 961, in render_annotated
    return self.render(context)
  File "/home/lgy/project/dj/env_2.7/local/lib/python2.7/site-packages/django/template/defaulttags.py", line 209, in render
    nodelist.append(node.render_annotated(context))
  File "/home/lgy/project/dj/env_2.7/local/lib/python2.7/site-packages/django/template/base.py", line 961, in render_annotated
    return self.render(context)
  File "/home/lgy/project/dj/env_2.7/local/lib/python2.7/site-packages/django/template/defaulttags.py", line 439, in render
    url = reverse(view_name, args=args, kwargs=kwargs, current_app=current_app)
  File "/home/lgy/project/dj/env_2.7/local/lib/python2.7/site-packages/django/urls/base.py", line 91, in reverse
    return force_text(iri_to_uri(resolver._reverse_with_prefix(view, prefix, *args, **kwargs)))
  File "/home/lgy/project/dj/env_2.7/local/lib/python2.7/site-packages/django/urls/resolvers.py", line 392, in _reverse_with_prefix
    (lookup_view_s, args, kwargs, len(patterns), patterns)
NoReverseMatch: Reverse for 'category' with arguments '()' and keyword arguments '{}' not found. 0 pattern(s) tried: []
2016-10-10 14:32:49,494 [Thread-2:140616301942528] [django.request:152] [base:get_response] [WARNING]- Not Found: /
2016-10-10 14:32:52,931 [Thread-4:140616301942528] [django.request:124] [exception:handle_uncaught_exception] [ERROR]- Internal Server Error: /blog/
Traceback (most recent call last):
  File "/home/lgy/project/dj/env_2.7/local/lib/python2.7/site-packages/django/core/handlers/exception.py", line 39, in inner
    response = get_response(request)
  File "/home/lgy/project/dj/env_2.7/local/lib/python2.7/site-packages/django/core/handlers/base.py", line 187, in _get_response
    response = self.process_exception_by_middleware(e, request)
  File "/home/lgy/project/dj/env_2.7/local/lib/python2.7/site-packages/django/core/handlers/base.py", line 185, in _get_response
    response = wrapped_callback(request, *callback_args, **callback_kwargs)
  File "/home/lgy/project/dj/blog_project/blog/views.py", line 41, in home
    return render(request,"index.html",locals())
  File "/home/lgy/project/dj/env_2.7/local/lib/python2.7/site-packages/django/shortcuts.py", line 30, in render
    content = loader.render_to_string(template_name, context, request, using=using)
  File "/home/lgy/project/dj/env_2.7/local/lib/python2.7/site-packages/django/template/loader.py", line 68, in render_to_string
    return template.render(context, request)
  File "/home/lgy/project/dj/env_2.7/local/lib/python2.7/site-packages/django/template/backends/django.py", line 66, in render
    return self.template.render(context)
  File "/home/lgy/project/dj/env_2.7/local/lib/python2.7/site-packages/django/template/base.py", line 206, in render
    with context.bind_template(self):
  File "/usr/lib/python2.7/contextlib.py", line 17, in __enter__
    return self.gen.next()
  File "/home/lgy/project/dj/env_2.7/local/lib/python2.7/site-packages/django/template/context.py", line 236, in bind_template
    updates.update(processor(self.request))
  File "/home/lgy/project/dj/blog_project/blog/views.py", line 20, in global_settings
    category_list = Category.objects.all().values("")
  File "/home/lgy/project/dj/env_2.7/local/lib/python2.7/site-packages/django/db/models/query.py", line 719, in values
    clone = self._values(*fields)
  File "/home/lgy/project/dj/env_2.7/local/lib/python2.7/site-packages/django/db/models/query.py", line 714, in _values
    query.add_fields(field_names, True)
  File "/home/lgy/project/dj/env_2.7/local/lib/python2.7/site-packages/django/db/models/sql/query.py", line 1644, in add_fields
    "Choices are: %s" % (name, ", ".join(names)))
FieldError: Cannot resolve keyword '' into field. Choices are: article, id, index, name
2016-10-10 14:34:30,155 [Thread-2:139910403589888] [django.request:124] [exception:handle_uncaught_exception] [ERROR]- Internal Server Error: /blog/
Traceback (most recent call last):
  File "/home/lgy/project/dj/env_2.7/local/lib/python2.7/site-packages/django/core/handlers/exception.py", line 39, in inner
    response = get_response(request)
  File "/home/lgy/project/dj/env_2.7/local/lib/python2.7/site-packages/django/core/handlers/base.py", line 187, in _get_response
    response = self.process_exception_by_middleware(e, request)
  File "/home/lgy/project/dj/env_2.7/local/lib/python2.7/site-packages/django/core/handlers/base.py", line 185, in _get_response
    response = wrapped_callback(request, *callback_args, **callback_kwargs)
  File "/home/lgy/project/dj/blog_project/blog/views.py", line 41, in home
    return render(request,"index.html",locals())
  File "/home/lgy/project/dj/env_2.7/local/lib/python2.7/site-packages/django/shortcuts.py", line 30, in render
    content = loader.render_to_string(template_name, context, request, using=using)
  File "/home/lgy/project/dj/env_2.7/local/lib/python2.7/site-packages/django/template/loader.py", line 68, in render_to_string
    return template.render(context, request)
  File "/home/lgy/project/dj/env_2.7/local/lib/python2.7/site-packages/django/template/backends/django.py", line 66, in render
    return self.template.render(context)
  File "/home/lgy/project/dj/env_2.7/local/lib/python2.7/site-packages/django/template/base.py", line 206, in render
    with context.bind_template(self):
  File "/usr/lib/python2.7/contextlib.py", line 17, in __enter__
    return self.gen.next()
  File "/home/lgy/project/dj/env_2.7/local/lib/python2.7/site-packages/django/template/context.py", line 236, in bind_template
    updates.update(processor(self.request))
  File "/home/lgy/project/dj/blog_project/blog/views.py", line 20, in global_settings
    category_list = Category.objects.all().values("")
  File "/home/lgy/project/dj/env_2.7/local/lib/python2.7/site-packages/django/db/models/query.py", line 719, in values
    clone = self._values(*fields)
  File "/home/lgy/project/dj/env_2.7/local/lib/python2.7/site-packages/django/db/models/query.py", line 714, in _values
    query.add_fields(field_names, True)
  File "/home/lgy/project/dj/env_2.7/local/lib/python2.7/site-packages/django/db/models/sql/query.py", line 1644, in add_fields
    "Choices are: %s" % (name, ", ".join(names)))
FieldError: Cannot resolve keyword '' into field. Choices are: article, id, index, name
2016-10-10 14:34:31,768 [Thread-3:139910403589888] [django.request:124] [exception:handle_uncaught_exception] [ERROR]- Internal Server Error: /blog/
Traceback (most recent call last):
  File "/home/lgy/project/dj/env_2.7/local/lib/python2.7/site-packages/django/core/handlers/exception.py", line 39, in inner
    response = get_response(request)
  File "/home/lgy/project/dj/env_2.7/local/lib/python2.7/site-packages/django/core/handlers/base.py", line 187, in _get_response
    response = self.process_exception_by_middleware(e, request)
  File "/home/lgy/project/dj/env_2.7/local/lib/python2.7/site-packages/django/core/handlers/base.py", line 185, in _get_response
    response = wrapped_callback(request, *callback_args, **callback_kwargs)
  File "/home/lgy/project/dj/blog_project/blog/views.py", line 41, in home
    return render(request,"index.html",locals())
  File "/home/lgy/project/dj/env_2.7/local/lib/python2.7/site-packages/django/shortcuts.py", line 30, in render
    content = loader.render_to_string(template_name, context, request, using=using)
  File "/home/lgy/project/dj/env_2.7/local/lib/python2.7/site-packages/django/template/loader.py", line 68, in render_to_string
    return template.render(context, request)
  File "/home/lgy/project/dj/env_2.7/local/lib/python2.7/site-packages/django/template/backends/django.py", line 66, in render
    return self.template.render(context)
  File "/home/lgy/project/dj/env_2.7/local/lib/python2.7/site-packages/django/template/base.py", line 206, in render
    with context.bind_template(self):
  File "/usr/lib/python2.7/contextlib.py", line 17, in __enter__
    return self.gen.next()
  File "/home/lgy/project/dj/env_2.7/local/lib/python2.7/site-packages/django/template/context.py", line 236, in bind_template
    updates.update(processor(self.request))
  File "/home/lgy/project/dj/blog_project/blog/views.py", line 20, in global_settings
    category_list = Category.objects.all().values("")
  File "/home/lgy/project/dj/env_2.7/local/lib/python2.7/site-packages/django/db/models/query.py", line 719, in values
    clone = self._values(*fields)
  File "/home/lgy/project/dj/env_2.7/local/lib/python2.7/site-packages/django/db/models/query.py", line 714, in _values
    query.add_fields(field_names, True)
  File "/home/lgy/project/dj/env_2.7/local/lib/python2.7/site-packages/django/db/models/sql/query.py", line 1644, in add_fields
    "Choices are: %s" % (name, ", ".join(names)))
FieldError: Cannot resolve keyword '' into field. Choices are: article, id, index, name
2016-10-10 14:35:31,926 [Thread-2:140593329194752] [django.request:124] [exception:handle_uncaught_exception] [ERROR]- Internal Server Error: /blog/
Traceback (most recent call last):
  File "/home/lgy/project/dj/env_2.7/local/lib/python2.7/site-packages/django/core/handlers/exception.py", line 39, in inner
    response = get_response(request)
  File "/home/lgy/project/dj/env_2.7/local/lib/python2.7/site-packages/django/core/handlers/base.py", line 187, in _get_response
    response = self.process_exception_by_middleware(e, request)
  File "/home/lgy/project/dj/env_2.7/local/lib/python2.7/site-packages/django/core/handlers/base.py", line 185, in _get_response
    response = wrapped_callback(request, *callback_args, **callback_kwargs)
  File "/home/lgy/project/dj/blog_project/blog/views.py", line 42, in home
    return render(request,"index.html",locals())
  File "/home/lgy/project/dj/env_2.7/local/lib/python2.7/site-packages/django/shortcuts.py", line 30, in render
    content = loader.render_to_string(template_name, context, request, using=using)
  File "/home/lgy/project/dj/env_2.7/local/lib/python2.7/site-packages/django/template/loader.py", line 68, in render_to_string
    return template.render(context, request)
  File "/home/lgy/project/dj/env_2.7/local/lib/python2.7/site-packages/django/template/backends/django.py", line 66, in render
    return self.template.render(context)
  File "/home/lgy/project/dj/env_2.7/local/lib/python2.7/site-packages/django/template/base.py", line 206, in render
    with context.bind_template(self):
  File "/usr/lib/python2.7/contextlib.py", line 17, in __enter__
    return self.gen.next()
  File "/home/lgy/project/dj/env_2.7/local/lib/python2.7/site-packages/django/template/context.py", line 236, in bind_template
    updates.update(processor(self.request))
  File "/home/lgy/project/dj/blog_project/blog/views.py", line 20, in global_settings
    category_list = Category.objects.all().values("")
  File "/home/lgy/project/dj/env_2.7/local/lib/python2.7/site-packages/django/db/models/query.py", line 719, in values
    clone = self._values(*fields)
  File "/home/lgy/project/dj/env_2.7/local/lib/python2.7/site-packages/django/db/models/query.py", line 714, in _values
    query.add_fields(field_names, True)
  File "/home/lgy/project/dj/env_2.7/local/lib/python2.7/site-packages/django/db/models/sql/query.py", line 1644, in add_fields
    "Choices are: %s" % (name, ", ".join(names)))
FieldError: Cannot resolve keyword '' into field. Choices are: article, id, index, name
2016-10-10 14:36:05,355 [Thread-2:140138595690240] [django.request:124] [exception:handle_uncaught_exception] [ERROR]- Internal Server Error: /blog/
Traceback (most recent call last):
  File "/home/lgy/project/dj/env_2.7/local/lib/python2.7/site-packages/django/core/handlers/exception.py", line 39, in inner
    response = get_response(request)
  File "/home/lgy/project/dj/env_2.7/local/lib/python2.7/site-packages/django/core/handlers/base.py", line 187, in _get_response
    response = self.process_exception_by_middleware(e, request)
  File "/home/lgy/project/dj/env_2.7/local/lib/python2.7/site-packages/django/core/handlers/base.py", line 185, in _get_response
    response = wrapped_callback(request, *callback_args, **callback_kwargs)
  File "/home/lgy/project/dj/blog_project/blog/views.py", line 42, in home
    return render(request,"index.html",locals())
  File "/home/lgy/project/dj/env_2.7/local/lib/python2.7/site-packages/django/shortcuts.py", line 30, in render
    content = loader.render_to_string(template_name, context, request, using=using)
  File "/home/lgy/project/dj/env_2.7/local/lib/python2.7/site-packages/django/template/loader.py", line 68, in render_to_string
    return template.render(context, request)
  File "/home/lgy/project/dj/env_2.7/local/lib/python2.7/site-packages/django/template/backends/django.py", line 66, in render
    return self.template.render(context)
  File "/home/lgy/project/dj/env_2.7/local/lib/python2.7/site-packages/django/template/base.py", line 208, in render
    return self._render(context)
  File "/home/lgy/project/dj/env_2.7/local/lib/python2.7/site-packages/django/template/base.py", line 199, in _render
    return self.nodelist.render(context)
  File "/home/lgy/project/dj/env_2.7/local/lib/python2.7/site-packages/django/template/base.py", line 994, in render
    bit = node.render_annotated(context)
  File "/home/lgy/project/dj/env_2.7/local/lib/python2.7/site-packages/django/template/base.py", line 961, in render_annotated
    return self.render(context)
  File "/home/lgy/project/dj/env_2.7/local/lib/python2.7/site-packages/django/template/loader_tags.py", line 174, in render
    return compiled_parent._render(context)
  File "/home/lgy/project/dj/env_2.7/local/lib/python2.7/site-packages/django/template/base.py", line 199, in _render
    return self.nodelist.render(context)
  File "/home/lgy/project/dj/env_2.7/local/lib/python2.7/site-packages/django/template/base.py", line 994, in render
    bit = node.render_annotated(context)
  File "/home/lgy/project/dj/env_2.7/local/lib/python2.7/site-packages/django/template/base.py", line 961, in render_annotated
    return self.render(context)
  File "/home/lgy/project/dj/env_2.7/local/lib/python2.7/site-packages/django/template/defaulttags.py", line 209, in render
    nodelist.append(node.render_annotated(context))
  File "/home/lgy/project/dj/env_2.7/local/lib/python2.7/site-packages/django/template/base.py", line 961, in render_annotated
    return self.render(context)
  File "/home/lgy/project/dj/env_2.7/local/lib/python2.7/site-packages/django/template/defaulttags.py", line 439, in render
    url = reverse(view_name, args=args, kwargs=kwargs, current_app=current_app)
  File "/home/lgy/project/dj/env_2.7/local/lib/python2.7/site-packages/django/urls/base.py", line 91, in reverse
    return force_text(iri_to_uri(resolver._reverse_with_prefix(view, prefix, *args, **kwargs)))
  File "/home/lgy/project/dj/env_2.7/local/lib/python2.7/site-packages/django/urls/resolvers.py", line 392, in _reverse_with_prefix
    (lookup_view_s, args, kwargs, len(patterns), patterns)
NoReverseMatch: Reverse for 'category' with arguments '()' and keyword arguments '{}' not found. 0 pattern(s) tried: []
2016-10-10 14:38:40,366 [Thread-7:140308556617472] [django.request:152] [base:get_response] [WARNING]- Not Found: /
2016-10-10 14:40:13,724 [Thread-3:140697049315072] [django.request:124] [exception:handle_uncaught_exception] [ERROR]- Internal Server Error: /
Traceback (most recent call last):
  File "/home/lgy/project/dj/env_2.7/local/lib/python2.7/site-packages/django/core/handlers/exception.py", line 39, in inner
    response = get_response(request)
  File "/home/lgy/project/dj/env_2.7/local/lib/python2.7/site-packages/django/core/handlers/base.py", line 172, in _get_response
    resolver_match = resolver.resolve(request.path_info)
  File "/home/lgy/project/dj/env_2.7/local/lib/python2.7/site-packages/django/urls/resolvers.py", line 272, in resolve
    sub_match = pattern.resolve(new_path)
  File "/home/lgy/project/dj/env_2.7/local/lib/python2.7/site-packages/django/urls/resolvers.py", line 130, in resolve
    kwargs.update(self.default_args)
ValueError: dictionary update sequence element #0 has length 1; 2 is required
2016-10-10 14:41:42,911 [Thread-4:140697049315072] [django.request:124] [exception:handle_uncaught_exception] [ERROR]- Internal Server Error: /
Traceback (most recent call last):
  File "/home/lgy/project/dj/env_2.7/local/lib/python2.7/site-packages/django/core/handlers/exception.py", line 39, in inner
    response = get_response(request)
  File "/home/lgy/project/dj/env_2.7/local/lib/python2.7/site-packages/django/core/handlers/base.py", line 172, in _get_response
    resolver_match = resolver.resolve(request.path_info)
  File "/home/lgy/project/dj/env_2.7/local/lib/python2.7/site-packages/django/urls/resolvers.py", line 272, in resolve
    sub_match = pattern.resolve(new_path)
  File "/home/lgy/project/dj/env_2.7/local/lib/python2.7/site-packages/django/urls/resolvers.py", line 130, in resolve
    kwargs.update(self.default_args)
ValueError: dictionary update sequence element #0 has length 1; 2 is required
2016-10-10 14:42:18,338 [Thread-2:140112000243456] [django.request:152] [base:get_response] [WARNING]- Not Found: /
2016-10-10 14:42:26,166 [Thread-2:140618772772608] [django.request:124] [exception:handle_uncaught_exception] [ERROR]- Internal Server Error: /
Traceback (most recent call last):
  File "/home/lgy/project/dj/env_2.7/local/lib/python2.7/site-packages/django/core/handlers/exception.py", line 39, in inner
    response = get_response(request)
  File "/home/lgy/project/dj/env_2.7/local/lib/python2.7/site-packages/django/core/handlers/base.py", line 172, in _get_response
    resolver_match = resolver.resolve(request.path_info)
  File "/home/lgy/project/dj/env_2.7/local/lib/python2.7/site-packages/django/urls/resolvers.py", line 272, in resolve
    sub_match = pattern.resolve(new_path)
  File "/home/lgy/project/dj/env_2.7/local/lib/python2.7/site-packages/django/urls/resolvers.py", line 130, in resolve
    kwargs.update(self.default_args)
ValueError: dictionary update sequence element #0 has length 1; 2 is required
2016-10-10 15:20:08,803 [Thread-2:140624342808320] [django.request:124] [exception:handle_uncaught_exception] [ERROR]- Internal Server Error: /
Traceback (most recent call last):
  File "/home/lgy/project/dj/env_2.7/local/lib/python2.7/site-packages/django/core/handlers/exception.py", line 39, in inner
    response = get_response(request)
  File "/home/lgy/project/dj/env_2.7/local/lib/python2.7/site-packages/django/core/handlers/base.py", line 187, in _get_response
    response = self.process_exception_by_middleware(e, request)
  File "/home/lgy/project/dj/env_2.7/local/lib/python2.7/site-packages/django/core/handlers/base.py", line 185, in _get_response
    response = wrapped_callback(request, *callback_args, **callback_kwargs)
  File "/home/lgy/project/dj/blog_project/blog/views.py", line 48, in home
    return render(request,"index.html",locals())
  File "/home/lgy/project/dj/env_2.7/local/lib/python2.7/site-packages/django/shortcuts.py", line 30, in render
    content = loader.render_to_string(template_name, context, request, using=using)
  File "/home/lgy/project/dj/env_2.7/local/lib/python2.7/site-packages/django/template/loader.py", line 68, in render_to_string
    return template.render(context, request)
  File "/home/lgy/project/dj/env_2.7/local/lib/python2.7/site-packages/django/template/backends/django.py", line 66, in render
    return self.template.render(context)
  File "/home/lgy/project/dj/env_2.7/local/lib/python2.7/site-packages/django/template/base.py", line 206, in render
    with context.bind_template(self):
  File "/usr/lib/python2.7/contextlib.py", line 17, in __enter__
    return self.gen.next()
  File "/home/lgy/project/dj/env_2.7/local/lib/python2.7/site-packages/django/template/context.py", line 236, in bind_template
    updates.update(processor(self.request))
  File "/home/lgy/project/dj/blog_project/blog/views.py", line 32, in global_settings
    article_comment_list = [Article.objects.get(pk=comment.article) for comment in comment_list]
AttributeError: 'dict' object has no attribute 'article'
2016-10-11 03:22:37,244 [Thread-2:139849356748544] [django.request:124] [exception:handle_uncaught_exception] [ERROR]- Internal Server Error: /
Traceback (most recent call last):
  File "/home/lgy/project/dj/env_2.7/local/lib/python2.7/site-packages/django/core/handlers/exception.py", line 39, in inner
    response = get_response(request)
  File "/home/lgy/project/dj/env_2.7/local/lib/python2.7/site-packages/django/core/handlers/base.py", line 187, in _get_response
    response = self.process_exception_by_middleware(e, request)
  File "/home/lgy/project/dj/env_2.7/local/lib/python2.7/site-packages/django/core/handlers/base.py", line 185, in _get_response
    response = wrapped_callback(request, *callback_args, **callback_kwargs)
  File "/home/lgy/project/dj/blog_project/blog/views.py", line 45, in home
    return render(request,"index.html",locals())
  File "/home/lgy/project/dj/env_2.7/local/lib/python2.7/site-packages/django/shortcuts.py", line 30, in render
    content = loader.render_to_string(template_name, context, request, using=using)
  File "/home/lgy/project/dj/env_2.7/local/lib/python2.7/site-packages/django/template/loader.py", line 67, in render_to_string
    template = get_template(template_name, using=using)
  File "/home/lgy/project/dj/env_2.7/local/lib/python2.7/site-packages/django/template/loader.py", line 18, in get_template
    engines = _engine_list(using)
  File "/home/lgy/project/dj/env_2.7/local/lib/python2.7/site-packages/django/template/loader.py", line 72, in _engine_list
    return engines.all() if using is None else [engines[using]]
  File "/home/lgy/project/dj/env_2.7/local/lib/python2.7/site-packages/django/template/utils.py", line 89, in all
    return [self[alias] for alias in self]
  File "/home/lgy/project/dj/env_2.7/local/lib/python2.7/site-packages/django/template/utils.py", line 80, in __getitem__
    engine = engine_cls(params)
  File "/home/lgy/project/dj/env_2.7/local/lib/python2.7/site-packages/django/template/backends/django.py", line 30, in __init__
    options['libraries'] = self.get_templatetag_libraries(libraries)
  File "/home/lgy/project/dj/env_2.7/local/lib/python2.7/site-packages/django/template/backends/django.py", line 48, in get_templatetag_libraries
    libraries = get_installed_libraries()
  File "/home/lgy/project/dj/env_2.7/local/lib/python2.7/site-packages/django/template/backends/django.py", line 113, in get_installed_libraries
    for name in get_package_libraries(pkg):
  File "/home/lgy/project/dj/env_2.7/local/lib/python2.7/site-packages/django/template/backends/django.py", line 126, in get_package_libraries
    module = import_module(entry[1])
  File "/usr/lib/python2.7/importlib/__init__.py", line 37, in import_module
    __import__(name)
  File "/home/lgy/project/dj/blog_project/blog/templatetags/filter.py", line 5
SyntaxError: Non-ASCII character '\xe8' in file /home/lgy/project/dj/blog_project/blog/templatetags/filter.py on line 5, but no encoding declared; see http://python.org/dev/peps/pep-0263/ for details
2016-10-11 03:23:14,605 [Thread-8:139849331570432] [django.request:124] [exception:handle_uncaught_exception] [ERROR]- Internal Server Error: /
Traceback (most recent call last):
  File "/home/lgy/project/dj/env_2.7/local/lib/python2.7/site-packages/django/core/handlers/exception.py", line 39, in inner
    response = get_response(request)
  File "/home/lgy/project/dj/env_2.7/local/lib/python2.7/site-packages/django/core/handlers/base.py", line 187, in _get_response
    response = self.process_exception_by_middleware(e, request)
  File "/home/lgy/project/dj/env_2.7/local/lib/python2.7/site-packages/django/core/handlers/base.py", line 185, in _get_response
    response = wrapped_callback(request, *callback_args, **callback_kwargs)
  File "/home/lgy/project/dj/blog_project/blog/views.py", line 45, in home
    return render(request,"index.html",locals())
  File "/home/lgy/project/dj/env_2.7/local/lib/python2.7/site-packages/django/shortcuts.py", line 30, in render
    content = loader.render_to_string(template_name, context, request, using=using)
  File "/home/lgy/project/dj/env_2.7/local/lib/python2.7/site-packages/django/template/loader.py", line 67, in render_to_string
    template = get_template(template_name, using=using)
  File "/home/lgy/project/dj/env_2.7/local/lib/python2.7/site-packages/django/template/loader.py", line 21, in get_template
    return engine.get_template(template_name)
  File "/home/lgy/project/dj/env_2.7/local/lib/python2.7/site-packages/django/template/backends/django.py", line 39, in get_template
    return Template(self.engine.get_template(template_name), self)
  File "/home/lgy/project/dj/env_2.7/local/lib/python2.7/site-packages/django/template/engine.py", line 160, in get_template
    template, origin = self.find_template(template_name)
  File "/home/lgy/project/dj/env_2.7/local/lib/python2.7/site-packages/django/template/engine.py", line 134, in find_template
    name, template_dirs=dirs, skip=skip,
  File "/home/lgy/project/dj/env_2.7/local/lib/python2.7/site-packages/django/template/loaders/base.py", line 44, in get_template
    contents, origin, origin.template_name, self.engine,
  File "/home/lgy/project/dj/env_2.7/local/lib/python2.7/site-packages/django/template/base.py", line 191, in __init__
    self.nodelist = self.compile_nodelist()
  File "/home/lgy/project/dj/env_2.7/local/lib/python2.7/site-packages/django/template/base.py", line 233, in compile_nodelist
    return parser.parse()
  File "/home/lgy/project/dj/env_2.7/local/lib/python2.7/site-packages/django/template/base.py", line 518, in parse
    raise self.error(token, e)
TemplateSyntaxError: Could not parse the remainder: '{{' from '{{'
2016-10-11 03:24:58,277 [Thread-14:139849348355840] [django.request:124] [exception:handle_uncaught_exception] [ERROR]- Internal Server Error: /
Traceback (most recent call last):
  File "/home/lgy/project/dj/env_2.7/local/lib/python2.7/site-packages/django/core/handlers/exception.py", line 39, in inner
    response = get_response(request)
  File "/home/lgy/project/dj/env_2.7/local/lib/python2.7/site-packages/django/core/handlers/base.py", line 187, in _get_response
    response = self.process_exception_by_middleware(e, request)
  File "/home/lgy/project/dj/env_2.7/local/lib/python2.7/site-packages/django/core/handlers/base.py", line 185, in _get_response
    response = wrapped_callback(request, *callback_args, **callback_kwargs)
  File "/home/lgy/project/dj/blog_project/blog/views.py", line 45, in home
    return render(request,"index.html",locals())
  File "/home/lgy/project/dj/env_2.7/local/lib/python2.7/site-packages/django/shortcuts.py", line 30, in render
    content = loader.render_to_string(template_name, context, request, using=using)
  File "/home/lgy/project/dj/env_2.7/local/lib/python2.7/site-packages/django/template/loader.py", line 67, in render_to_string
    template = get_template(template_name, using=using)
  File "/home/lgy/project/dj/env_2.7/local/lib/python2.7/site-packages/django/template/loader.py", line 21, in get_template
    return engine.get_template(template_name)
  File "/home/lgy/project/dj/env_2.7/local/lib/python2.7/site-packages/django/template/backends/django.py", line 39, in get_template
    return Template(self.engine.get_template(template_name), self)
  File "/home/lgy/project/dj/env_2.7/local/lib/python2.7/site-packages/django/template/engine.py", line 160, in get_template
    template, origin = self.find_template(template_name)
  File "/home/lgy/project/dj/env_2.7/local/lib/python2.7/site-packages/django/template/engine.py", line 134, in find_template
    name, template_dirs=dirs, skip=skip,
  File "/home/lgy/project/dj/env_2.7/local/lib/python2.7/site-packages/django/template/loaders/base.py", line 44, in get_template
    contents, origin, origin.template_name, self.engine,
  File "/home/lgy/project/dj/env_2.7/local/lib/python2.7/site-packages/django/template/base.py", line 191, in __init__
    self.nodelist = self.compile_nodelist()
  File "/home/lgy/project/dj/env_2.7/local/lib/python2.7/site-packages/django/template/base.py", line 233, in compile_nodelist
    return parser.parse()
  File "/home/lgy/project/dj/env_2.7/local/lib/python2.7/site-packages/django/template/base.py", line 518, in parse
    raise self.error(token, e)
TemplateSyntaxError: Could not parse the remainder: '=' from 'id='
2016-10-11 03:29:19,618 [Thread-20:139849323177728] [django.request:124] [exception:handle_uncaught_exception] [ERROR]- Internal Server Error: /blog/article/3
Traceback (most recent call last):
  File "/home/lgy/project/dj/env_2.7/local/lib/python2.7/site-packages/django/core/handlers/exception.py", line 39, in inner
    response = get_response(request)
  File "/home/lgy/project/dj/env_2.7/local/lib/python2.7/site-packages/django/core/handlers/base.py", line 187, in _get_response
    response = self.process_exception_by_middleware(e, request)
  File "/home/lgy/project/dj/env_2.7/local/lib/python2.7/site-packages/django/core/handlers/base.py", line 185, in _get_response
    response = wrapped_callback(request, *callback_args, **callback_kwargs)
  File "/home/lgy/project/dj/blog_project/blog/views.py", line 68, in article
    article = Article.objects.get(id)
  File "/home/lgy/project/dj/env_2.7/local/lib/python2.7/site-packages/django/db/models/manager.py", line 85, in manager_method
    return getattr(self.get_queryset(), name)(*args, **kwargs)
  File "/home/lgy/project/dj/env_2.7/local/lib/python2.7/site-packages/django/db/models/query.py", line 376, in get
    clone = self.filter(*args, **kwargs)
  File "/home/lgy/project/dj/env_2.7/local/lib/python2.7/site-packages/django/db/models/query.py", line 796, in filter
    return self._filter_or_exclude(False, *args, **kwargs)
  File "/home/lgy/project/dj/env_2.7/local/lib/python2.7/site-packages/django/db/models/query.py", line 814, in _filter_or_exclude
    clone.query.add_q(Q(*args, **kwargs))
  File "/home/lgy/project/dj/env_2.7/local/lib/python2.7/site-packages/django/db/models/sql/query.py", line 1227, in add_q
    clause, _ = self._add_q(q_object, self.used_aliases)
  File "/home/lgy/project/dj/env_2.7/local/lib/python2.7/site-packages/django/db/models/sql/query.py", line 1253, in _add_q
    allow_joins=allow_joins, split_subq=split_subq,
  File "/home/lgy/project/dj/env_2.7/local/lib/python2.7/site-packages/django/db/models/sql/query.py", line 1130, in build_filter
    arg, value = filter_expr
ValueError: need more than 1 value to unpack
2016-10-11 03:30:25,564 [Thread-2:140067718547200] [django.request:124] [exception:handle_uncaught_exception] [ERROR]- Internal Server Error: /blog/article/3
Traceback (most recent call last):
  File "/home/lgy/project/dj/env_2.7/local/lib/python2.7/site-packages/django/core/handlers/exception.py", line 39, in inner
    response = get_response(request)
  File "/home/lgy/project/dj/env_2.7/local/lib/python2.7/site-packages/django/core/handlers/base.py", line 187, in _get_response
    response = self.process_exception_by_middleware(e, request)
  File "/home/lgy/project/dj/env_2.7/local/lib/python2.7/site-packages/django/core/handlers/base.py", line 185, in _get_response
    response = wrapped_callback(request, *callback_args, **callback_kwargs)
  File "/home/lgy/project/dj/blog_project/blog/views.py", line 72, in article
    return render(request,"article.html",locals())
  File "/home/lgy/project/dj/env_2.7/local/lib/python2.7/site-packages/django/shortcuts.py", line 30, in render
    content = loader.render_to_string(template_name, context, request, using=using)
  File "/home/lgy/project/dj/env_2.7/local/lib/python2.7/site-packages/django/template/loader.py", line 68, in render_to_string
    return template.render(context, request)
  File "/home/lgy/project/dj/env_2.7/local/lib/python2.7/site-packages/django/template/backends/django.py", line 66, in render
    return self.template.render(context)
  File "/home/lgy/project/dj/env_2.7/local/lib/python2.7/site-packages/django/template/base.py", line 208, in render
    return self._render(context)
  File "/home/lgy/project/dj/env_2.7/local/lib/python2.7/site-packages/django/template/base.py", line 199, in _render
    return self.nodelist.render(context)
  File "/home/lgy/project/dj/env_2.7/local/lib/python2.7/site-packages/django/template/base.py", line 994, in render
    bit = node.render_annotated(context)
  File "/home/lgy/project/dj/env_2.7/local/lib/python2.7/site-packages/django/template/base.py", line 961, in render_annotated
    return self.render(context)
  File "/home/lgy/project/dj/env_2.7/local/lib/python2.7/site-packages/django/template/loader_tags.py", line 174, in render
    return compiled_parent._render(context)
  File "/home/lgy/project/dj/env_2.7/local/lib/python2.7/site-packages/django/template/base.py", line 199, in _render
    return self.nodelist.render(context)
  File "/home/lgy/project/dj/env_2.7/local/lib/python2.7/site-packages/django/template/base.py", line 994, in render
    bit = node.render_annotated(context)
  File "/home/lgy/project/dj/env_2.7/local/lib/python2.7/site-packages/django/template/base.py", line 961, in render_annotated
    return self.render(context)
  File "/home/lgy/project/dj/env_2.7/local/lib/python2.7/site-packages/django/template/loader_tags.py", line 70, in render
    result = block.nodelist.render(context)
  File "/home/lgy/project/dj/env_2.7/local/lib/python2.7/site-packages/django/template/base.py", line 994, in render
    bit = node.render_annotated(context)
  File "/home/lgy/project/dj/env_2.7/local/lib/python2.7/site-packages/django/template/base.py", line 961, in render_annotated
    return self.render(context)
  File "/home/lgy/project/dj/env_2.7/local/lib/python2.7/site-packages/django/template/defaulttags.py", line 315, in render
    return nodelist.render(context)
  File "/home/lgy/project/dj/env_2.7/local/lib/python2.7/site-packages/django/template/base.py", line 994, in render
    bit = node.render_annotated(context)
  File "/home/lgy/project/dj/env_2.7/local/lib/python2.7/site-packages/django/template/base.py", line 961, in render_annotated
    return self.render(context)
  File "/home/lgy/project/dj/env_2.7/local/lib/python2.7/site-packages/django/template/defaulttags.py", line 439, in render
    url = reverse(view_name, args=args, kwargs=kwargs, current_app=current_app)
  File "/home/lgy/project/dj/env_2.7/local/lib/python2.7/site-packages/django/urls/base.py", line 91, in reverse
    return force_text(iri_to_uri(resolver._reverse_with_prefix(view, prefix, *args, **kwargs)))
  File "/home/lgy/project/dj/env_2.7/local/lib/python2.7/site-packages/django/urls/resolvers.py", line 392, in _reverse_with_prefix
    (lookup_view_s, args, kwargs, len(patterns), patterns)
NoReverseMatch: Reverse for 'logout' with arguments '()' and keyword arguments '{}' not found. 0 pattern(s) tried: []
2016-10-11 03:30:46,915 [Thread-2:140521257105152] [django.request:124] [exception:handle_uncaught_exception] [ERROR]- Internal Server Error: /blog/article/3
Traceback (most recent call last):
  File "/home/lgy/project/dj/env_2.7/local/lib/python2.7/site-packages/django/core/handlers/exception.py", line 39, in inner
    response = get_response(request)
  File "/home/lgy/project/dj/env_2.7/local/lib/python2.7/site-packages/django/core/handlers/base.py", line 187, in _get_response
    response = self.process_exception_by_middleware(e, request)
  File "/home/lgy/project/dj/env_2.7/local/lib/python2.7/site-packages/django/core/handlers/base.py", line 185, in _get_response
    response = wrapped_callback(request, *callback_args, **callback_kwargs)
  File "/home/lgy/project/dj/blog_project/blog/views.py", line 73, in article
    return render(request,"article.html",locals())
  File "/home/lgy/project/dj/env_2.7/local/lib/python2.7/site-packages/django/shortcuts.py", line 30, in render
    content = loader.render_to_string(template_name, context, request, using=using)
  File "/home/lgy/project/dj/env_2.7/local/lib/python2.7/site-packages/django/template/loader.py", line 68, in render_to_string
    return template.render(context, request)
  File "/home/lgy/project/dj/env_2.7/local/lib/python2.7/site-packages/django/template/backends/django.py", line 66, in render
    return self.template.render(context)
  File "/home/lgy/project/dj/env_2.7/local/lib/python2.7/site-packages/django/template/base.py", line 208, in render
    return self._render(context)
  File "/home/lgy/project/dj/env_2.7/local/lib/python2.7/site-packages/django/template/base.py", line 199, in _render
    return self.nodelist.render(context)
  File "/home/lgy/project/dj/env_2.7/local/lib/python2.7/site-packages/django/template/base.py", line 994, in render
    bit = node.render_annotated(context)
  File "/home/lgy/project/dj/env_2.7/local/lib/python2.7/site-packages/django/template/base.py", line 961, in render_annotated
    return self.render(context)
  File "/home/lgy/project/dj/env_2.7/local/lib/python2.7/site-packages/django/template/loader_tags.py", line 174, in render
    return compiled_parent._render(context)
  File "/home/lgy/project/dj/env_2.7/local/lib/python2.7/site-packages/django/template/base.py", line 199, in _render
    return self.nodelist.render(context)
  File "/home/lgy/project/dj/env_2.7/local/lib/python2.7/site-packages/django/template/base.py", line 994, in render
    bit = node.render_annotated(context)
  File "/home/lgy/project/dj/env_2.7/local/lib/python2.7/site-packages/django/template/base.py", line 961, in render_annotated
    return self.render(context)
  File "/home/lgy/project/dj/env_2.7/local/lib/python2.7/site-packages/django/template/loader_tags.py", line 70, in render
    result = block.nodelist.render(context)
  File "/home/lgy/project/dj/env_2.7/local/lib/python2.7/site-packages/django/template/base.py", line 994, in render
    bit = node.render_annotated(context)
  File "/home/lgy/project/dj/env_2.7/local/lib/python2.7/site-packages/django/template/base.py", line 961, in render_annotated
    return self.render(context)
  File "/home/lgy/project/dj/env_2.7/local/lib/python2.7/site-packages/django/template/base.py", line 1044, in render
    output = self.filter_expression.resolve(context)
  File "/home/lgy/project/dj/env_2.7/local/lib/python2.7/site-packages/django/template/base.py", line 739, in resolve
    new_obj = func(obj, *arg_vals)
  File "/home/lgy/project/dj/blog_project/blog/templatetags/filter.py", line 10, in month_to_upper
    return ["一","二","三","四","五","六","七","八","九","十","十一","十二"][key.month - 1]
AttributeError: 'str' object has no attribute 'month'
2016-10-11 03:32:12,110 [Thread-2:140536372438784] [django.request:124] [exception:handle_uncaught_exception] [ERROR]- Internal Server Error: /blog/article/3
Traceback (most recent call last):
  File "/home/lgy/project/dj/env_2.7/local/lib/python2.7/site-packages/django/core/handlers/exception.py", line 39, in inner
    response = get_response(request)
  File "/home/lgy/project/dj/env_2.7/local/lib/python2.7/site-packages/django/core/handlers/base.py", line 187, in _get_response
    response = self.process_exception_by_middleware(e, request)
  File "/home/lgy/project/dj/env_2.7/local/lib/python2.7/site-packages/django/core/handlers/base.py", line 185, in _get_response
    response = wrapped_callback(request, *callback_args, **callback_kwargs)
  File "/home/lgy/project/dj/blog_project/blog/views.py", line 73, in article
    return render(request,"article.html",locals())
  File "/home/lgy/project/dj/env_2.7/local/lib/python2.7/site-packages/django/shortcuts.py", line 30, in render
    content = loader.render_to_string(template_name, context, request, using=using)
  File "/home/lgy/project/dj/env_2.7/local/lib/python2.7/site-packages/django/template/loader.py", line 68, in render_to_string
    return template.render(context, request)
  File "/home/lgy/project/dj/env_2.7/local/lib/python2.7/site-packages/django/template/backends/django.py", line 66, in render
    return self.template.render(context)
  File "/home/lgy/project/dj/env_2.7/local/lib/python2.7/site-packages/django/template/base.py", line 208, in render
    return self._render(context)
  File "/home/lgy/project/dj/env_2.7/local/lib/python2.7/site-packages/django/template/base.py", line 199, in _render
    return self.nodelist.render(context)
  File "/home/lgy/project/dj/env_2.7/local/lib/python2.7/site-packages/django/template/base.py", line 994, in render
    bit = node.render_annotated(context)
  File "/home/lgy/project/dj/env_2.7/local/lib/python2.7/site-packages/django/template/base.py", line 961, in render_annotated
    return self.render(context)
  File "/home/lgy/project/dj/env_2.7/local/lib/python2.7/site-packages/django/template/loader_tags.py", line 174, in render
    return compiled_parent._render(context)
  File "/home/lgy/project/dj/env_2.7/local/lib/python2.7/site-packages/django/template/base.py", line 199, in _render
    return self.nodelist.render(context)
  File "/home/lgy/project/dj/env_2.7/local/lib/python2.7/site-packages/django/template/base.py", line 994, in render
    bit = node.render_annotated(context)
  File "/home/lgy/project/dj/env_2.7/local/lib/python2.7/site-packages/django/template/base.py", line 961, in render_annotated
    return self.render(context)
  File "/home/lgy/project/dj/env_2.7/local/lib/python2.7/site-packages/django/template/loader_tags.py", line 70, in render
    result = block.nodelist.render(context)
  File "/home/lgy/project/dj/env_2.7/local/lib/python2.7/site-packages/django/template/base.py", line 994, in render
    bit = node.render_annotated(context)
  File "/home/lgy/project/dj/env_2.7/local/lib/python2.7/site-packages/django/template/base.py", line 961, in render_annotated
    return self.render(context)
  File "/home/lgy/project/dj/env_2.7/local/lib/python2.7/site-packages/django/template/defaulttags.py", line 315, in render
    return nodelist.render(context)
  File "/home/lgy/project/dj/env_2.7/local/lib/python2.7/site-packages/django/template/base.py", line 994, in render
    bit = node.render_annotated(context)
  File "/home/lgy/project/dj/env_2.7/local/lib/python2.7/site-packages/django/template/base.py", line 961, in render_annotated
    return self.render(context)
  File "/home/lgy/project/dj/env_2.7/local/lib/python2.7/site-packages/django/template/defaulttags.py", line 439, in render
    url = reverse(view_name, args=args, kwargs=kwargs, current_app=current_app)
  File "/home/lgy/project/dj/env_2.7/local/lib/python2.7/site-packages/django/urls/base.py", line 91, in reverse
    return force_text(iri_to_uri(resolver._reverse_with_prefix(view, prefix, *args, **kwargs)))
  File "/home/lgy/project/dj/env_2.7/local/lib/python2.7/site-packages/django/urls/resolvers.py", line 392, in _reverse_with_prefix
    (lookup_view_s, args, kwargs, len(patterns), patterns)
NoReverseMatch: Reverse for 'logout' with arguments '()' and keyword arguments '{}' not found. 0 pattern(s) tried: []
2016-10-11 03:34:36,918 [Thread-22:140536260835072] [django.request:152] [base:get_response] [WARNING]- Not Found: /uploads/kindeditor/2016/10/4e948a62-8d6a-11e6-bd56-54ee7574e650.png
2016-10-11 03:35:48,569 [Thread-31:140536260835072] [django.request:152] [base:get_response] [WARNING]- Not Found: /uploads/kindeditor/2016/10/4e948a62-8d6a-11e6-bd56-54ee7574e650.png
2016-10-11 03:40:21,414 [Thread-34:140536260835072] [django.request:152] [base:get_response] [WARNING]- Not Found: /uploads/kindeditor/2016/10/4e948a62-8d6a-11e6-bd56-54ee7574e650.png
2016-10-11 07:36:15,916 [Thread-55:140536287586048] [django.request:152] [base:get_response] [WARNING]- Not Found: /blog/article/article/
2016-10-11 07:36:24,697 [Thread-56:140536279193344] [django.request:152] [base:get_response] [WARNING]- Not Found: /blog/article/article/
2016-10-11 08:19:16,824 [Thread-2:139808116889344] [django.request:124] [exception:handle_uncaught_exception] [ERROR]- Internal Server Error: /blog/article/3
Traceback (most recent call last):
  File "/home/lgy/project/dj/env_2.7/local/lib/python2.7/site-packages/django/core/handlers/exception.py", line 39, in inner
    response = get_response(request)
  File "/home/lgy/project/dj/env_2.7/local/lib/python2.7/site-packages/django/core/handlers/base.py", line 187, in _get_response
    response = self.process_exception_by_middleware(e, request)
  File "/home/lgy/project/dj/env_2.7/local/lib/python2.7/site-packages/django/core/handlers/base.py", line 185, in _get_response
    response = wrapped_callback(request, *callback_args, **callback_kwargs)
  File "/home/lgy/project/dj/blog_project/blog/views.py", line 71, in article
    comment_list = get_comment(request,id)
  File "/home/lgy/project/dj/blog_project/blog/views.py", line 123, in get_comment
    return parent_comment
UnboundLocalError: local variable 'parent_comment' referenced before assignment
2016-10-11 08:20:34,283 [Thread-2:139764260275968] [django.request:124] [exception:handle_uncaught_exception] [ERROR]- Internal Server Error: /blog/article/3
Traceback (most recent call last):
  File "/home/lgy/project/dj/env_2.7/local/lib/python2.7/site-packages/django/core/handlers/exception.py", line 39, in inner
    response = get_response(request)
  File "/home/lgy/project/dj/env_2.7/local/lib/python2.7/site-packages/django/core/handlers/base.py", line 187, in _get_response
    response = self.process_exception_by_middleware(e, request)
  File "/home/lgy/project/dj/env_2.7/local/lib/python2.7/site-packages/django/core/handlers/base.py", line 185, in _get_response
    response = wrapped_callback(request, *callback_args, **callback_kwargs)
  File "/home/lgy/project/dj/blog_project/blog/views.py", line 71, in article
    comment_list = get_comment(request,id)
  File "/home/lgy/project/dj/blog_project/blog/views.py", line 123, in get_comment
    return parent_comment
UnboundLocalError: local variable 'parent_comment' referenced before assignment
2016-10-11 08:24:13,725 [Thread-2:140307683878656] [django.request:124] [exception:handle_uncaught_exception] [ERROR]- Internal Server Error: /blog/article/3
Traceback (most recent call last):
  File "/home/lgy/project/dj/env_2.7/local/lib/python2.7/site-packages/django/core/handlers/exception.py", line 39, in inner
    response = get_response(request)
  File "/home/lgy/project/dj/env_2.7/local/lib/python2.7/site-packages/django/core/handlers/base.py", line 187, in _get_response
    response = self.process_exception_by_middleware(e, request)
  File "/home/lgy/project/dj/env_2.7/local/lib/python2.7/site-packages/django/core/handlers/base.py", line 185, in _get_response
    response = wrapped_callback(request, *callback_args, **callback_kwargs)
  File "/home/lgy/project/dj/blog_project/blog/views.py", line 71, in article
    comment_list = get_comment(request,id)
  File "/home/lgy/project/dj/blog_project/blog/views.py", line 126, in get_comment
    return parent_comment
NameError: global name 'parent_comment' is not defined
2016-10-11 08:43:47,156 [Thread-2:140140264371968] [django.request:124] [exception:handle_uncaught_exception] [ERROR]- Internal Server Error: /blog/article/3
Traceback (most recent call last):
  File "/home/lgy/project/dj/env_2.7/local/lib/python2.7/site-packages/django/core/handlers/exception.py", line 39, in inner
    response = get_response(request)
  File "/home/lgy/project/dj/env_2.7/local/lib/python2.7/site-packages/django/core/handlers/base.py", line 187, in _get_response
    response = self.process_exception_by_middleware(e, request)
  File "/home/lgy/project/dj/env_2.7/local/lib/python2.7/site-packages/django/core/handlers/base.py", line 185, in _get_response
    response = wrapped_callback(request, *callback_args, **callback_kwargs)
  File "/home/lgy/project/dj/blog_project/blog/views.py", line 75, in article
    return render(request,"article.html",locals())
  File "/home/lgy/project/dj/env_2.7/local/lib/python2.7/site-packages/django/shortcuts.py", line 30, in render
    content = loader.render_to_string(template_name, context, request, using=using)
  File "/home/lgy/project/dj/env_2.7/local/lib/python2.7/site-packages/django/template/loader.py", line 68, in render_to_string
    return template.render(context, request)
  File "/home/lgy/project/dj/env_2.7/local/lib/python2.7/site-packages/django/template/backends/django.py", line 66, in render
    return self.template.render(context)
  File "/home/lgy/project/dj/env_2.7/local/lib/python2.7/site-packages/django/template/base.py", line 208, in render
    return self._render(context)
  File "/home/lgy/project/dj/env_2.7/local/lib/python2.7/site-packages/django/template/base.py", line 199, in _render
    return self.nodelist.render(context)
  File "/home/lgy/project/dj/env_2.7/local/lib/python2.7/site-packages/django/template/base.py", line 994, in render
    bit = node.render_annotated(context)
  File "/home/lgy/project/dj/env_2.7/local/lib/python2.7/site-packages/django/template/base.py", line 961, in render_annotated
    return self.render(context)
  File "/home/lgy/project/dj/env_2.7/local/lib/python2.7/site-packages/django/template/loader_tags.py", line 174, in render
    return compiled_parent._render(context)
  File "/home/lgy/project/dj/env_2.7/local/lib/python2.7/site-packages/django/template/base.py", line 199, in _render
    return self.nodelist.render(context)
  File "/home/lgy/project/dj/env_2.7/local/lib/python2.7/site-packages/django/template/base.py", line 994, in render
    bit = node.render_annotated(context)
  File "/home/lgy/project/dj/env_2.7/local/lib/python2.7/site-packages/django/template/base.py", line 961, in render_annotated
    return self.render(context)
  File "/home/lgy/project/dj/env_2.7/local/lib/python2.7/site-packages/django/template/loader_tags.py", line 70, in render
    result = block.nodelist.render(context)
  File "/home/lgy/project/dj/env_2.7/local/lib/python2.7/site-packages/django/template/base.py", line 994, in render
    bit = node.render_annotated(context)
  File "/home/lgy/project/dj/env_2.7/local/lib/python2.7/site-packages/django/template/base.py", line 961, in render_annotated
    return self.render(context)
  File "/home/lgy/project/dj/env_2.7/local/lib/python2.7/site-packages/django/template/defaulttags.py", line 209, in render
    nodelist.append(node.render_annotated(context))
  File "/home/lgy/project/dj/env_2.7/local/lib/python2.7/site-packages/django/template/base.py", line 961, in render_annotated
    return self.render(context)
  File "/home/lgy/project/dj/env_2.7/local/lib/python2.7/site-packages/django/template/defaulttags.py", line 165, in render
    values = list(values)
TypeError: 'Comment' object is not iterable
2016-10-11 08:44:50,418 [Thread-2:139733606856448] [django.request:124] [exception:handle_uncaught_exception] [ERROR]- Internal Server Error: /blog/article/3
Traceback (most recent call last):
  File "/home/lgy/project/dj/env_2.7/local/lib/python2.7/site-packages/django/core/handlers/exception.py", line 39, in inner
    response = get_response(request)
  File "/home/lgy/project/dj/env_2.7/local/lib/python2.7/site-packages/django/core/handlers/base.py", line 187, in _get_response
    response = self.process_exception_by_middleware(e, request)
  File "/home/lgy/project/dj/env_2.7/local/lib/python2.7/site-packages/django/core/handlers/base.py", line 185, in _get_response
    response = wrapped_callback(request, *callback_args, **callback_kwargs)
  File "/home/lgy/project/dj/blog_project/blog/views.py", line 75, in article
    return render(request,"article.html",locals())
  File "/home/lgy/project/dj/env_2.7/local/lib/python2.7/site-packages/django/shortcuts.py", line 30, in render
    content = loader.render_to_string(template_name, context, request, using=using)
  File "/home/lgy/project/dj/env_2.7/local/lib/python2.7/site-packages/django/template/loader.py", line 68, in render_to_string
    return template.render(context, request)
  File "/home/lgy/project/dj/env_2.7/local/lib/python2.7/site-packages/django/template/backends/django.py", line 66, in render
    return self.template.render(context)
  File "/home/lgy/project/dj/env_2.7/local/lib/python2.7/site-packages/django/template/base.py", line 208, in render
    return self._render(context)
  File "/home/lgy/project/dj/env_2.7/local/lib/python2.7/site-packages/django/template/base.py", line 199, in _render
    return self.nodelist.render(context)
  File "/home/lgy/project/dj/env_2.7/local/lib/python2.7/site-packages/django/template/base.py", line 994, in render
    bit = node.render_annotated(context)
  File "/home/lgy/project/dj/env_2.7/local/lib/python2.7/site-packages/django/template/base.py", line 961, in render_annotated
    return self.render(context)
  File "/home/lgy/project/dj/env_2.7/local/lib/python2.7/site-packages/django/template/loader_tags.py", line 174, in render
    return compiled_parent._render(context)
  File "/home/lgy/project/dj/env_2.7/local/lib/python2.7/site-packages/django/template/base.py", line 199, in _render
    return self.nodelist.render(context)
  File "/home/lgy/project/dj/env_2.7/local/lib/python2.7/site-packages/django/template/base.py", line 994, in render
    bit = node.render_annotated(context)
  File "/home/lgy/project/dj/env_2.7/local/lib/python2.7/site-packages/django/template/base.py", line 961, in render_annotated
    return self.render(context)
  File "/home/lgy/project/dj/env_2.7/local/lib/python2.7/site-packages/django/template/loader_tags.py", line 70, in render
    result = block.nodelist.render(context)
  File "/home/lgy/project/dj/env_2.7/local/lib/python2.7/site-packages/django/template/base.py", line 994, in render
    bit = node.render_annotated(context)
  File "/home/lgy/project/dj/env_2.7/local/lib/python2.7/site-packages/django/template/base.py", line 961, in render_annotated
    return self.render(context)
  File "/home/lgy/project/dj/env_2.7/local/lib/python2.7/site-packages/django/template/defaulttags.py", line 209, in render
    nodelist.append(node.render_annotated(context))
  File "/home/lgy/project/dj/env_2.7/local/lib/python2.7/site-packages/django/template/base.py", line 961, in render_annotated
    return self.render(context)
  File "/home/lgy/project/dj/env_2.7/local/lib/python2.7/site-packages/django/template/defaulttags.py", line 165, in render
    values = list(values)
TypeError: 'Comment' object is not iterable
2016-10-11 09:24:57,515 [Thread-6:139872379332352] [django.request:152] [base:get_response] [WARNING]- Not Found: /uploads/kindeditor/2016/10/4e948a62-8d6a-11e6-bd56-54ee7574e650.png
2016-10-11 14:56:24,011 [Thread-5:139655235335936] [django.request:124] [exception:handle_uncaught_exception] [ERROR]- Internal Server Error: /blog/comment_post/
Traceback (most recent call last):
  File "/home/lgy/project/dj/env_2.7/local/lib/python2.7/site-packages/django/core/handlers/exception.py", line 39, in inner
    response = get_response(request)
  File "/home/lgy/project/dj/env_2.7/local/lib/python2.7/site-packages/django/core/handlers/base.py", line 187, in _get_response
    response = self.process_exception_by_middleware(e, request)
  File "/home/lgy/project/dj/env_2.7/local/lib/python2.7/site-packages/django/core/handlers/base.py", line 185, in _get_response
    response = wrapped_callback(request, *callback_args, **callback_kwargs)
  File "/home/lgy/project/dj/blog_project/blog/views.py", line 167, in comment_post
    return render(request,"article.html",locals())
  File "/home/lgy/project/dj/env_2.7/local/lib/python2.7/site-packages/django/shortcuts.py", line 30, in render
    content = loader.render_to_string(template_name, context, request, using=using)
  File "/home/lgy/project/dj/env_2.7/local/lib/python2.7/site-packages/django/template/loader.py", line 68, in render_to_string
    return template.render(context, request)
  File "/home/lgy/project/dj/env_2.7/local/lib/python2.7/site-packages/django/template/backends/django.py", line 66, in render
    return self.template.render(context)
  File "/home/lgy/project/dj/env_2.7/local/lib/python2.7/site-packages/django/template/base.py", line 208, in render
    return self._render(context)
  File "/home/lgy/project/dj/env_2.7/local/lib/python2.7/site-packages/django/template/base.py", line 199, in _render
    return self.nodelist.render(context)
  File "/home/lgy/project/dj/env_2.7/local/lib/python2.7/site-packages/django/template/base.py", line 994, in render
    bit = node.render_annotated(context)
  File "/home/lgy/project/dj/env_2.7/local/lib/python2.7/site-packages/django/template/base.py", line 961, in render_annotated
    return self.render(context)
  File "/home/lgy/project/dj/env_2.7/local/lib/python2.7/site-packages/django/template/loader_tags.py", line 174, in render
    return compiled_parent._render(context)
  File "/home/lgy/project/dj/env_2.7/local/lib/python2.7/site-packages/django/template/base.py", line 199, in _render
    return self.nodelist.render(context)
  File "/home/lgy/project/dj/env_2.7/local/lib/python2.7/site-packages/django/template/base.py", line 994, in render
    bit = node.render_annotated(context)
  File "/home/lgy/project/dj/env_2.7/local/lib/python2.7/site-packages/django/template/base.py", line 961, in render_annotated
    return self.render(context)
  File "/home/lgy/project/dj/env_2.7/local/lib/python2.7/site-packages/django/template/loader_tags.py", line 70, in render
    result = block.nodelist.render(context)
  File "/home/lgy/project/dj/env_2.7/local/lib/python2.7/site-packages/django/template/base.py", line 994, in render
    bit = node.render_annotated(context)
  File "/home/lgy/project/dj/env_2.7/local/lib/python2.7/site-packages/django/template/base.py", line 961, in render_annotated
    return self.render(context)
  File "/home/lgy/project/dj/env_2.7/local/lib/python2.7/site-packages/django/template/base.py", line 1044, in render
    output = self.filter_expression.resolve(context)
  File "/home/lgy/project/dj/env_2.7/local/lib/python2.7/site-packages/django/template/base.py", line 739, in resolve
    new_obj = func(obj, *arg_vals)
  File "/home/lgy/project/dj/blog_project/blog/templatetags/filter.py", line 10, in month_to_upper
    return ["一","二","三","四","五","六","七","八","九","十","十一","十二"][key.month - 1]
AttributeError: 'str' object has no attribute 'month'
2016-10-11 15:21:55,082 [Thread-3:139669606774528] [django.request:124] [exception:handle_uncaught_exception] [ERROR]- Internal Server Error: /blog/logout/
Traceback (most recent call last):
  File "/home/lgy/project/dj/env_2.7/local/lib/python2.7/site-packages/django/core/handlers/exception.py", line 39, in inner
    response = get_response(request)
  File "/home/lgy/project/dj/env_2.7/local/lib/python2.7/site-packages/django/core/handlers/base.py", line 198, in _get_response
    "returned None instead." % (callback.__module__, view_name)
ValueError: The view blog.views.logout didn't return an HttpResponse object. It returned None instead.
2016-10-11 15:40:04,412 [Thread-13:139863494072064] [django.request:152] [base:get_response] [WARNING]- Not Found: /blog/login/css/reglogin.css
2016-10-11 15:40:09,072 [Thread-15:139863494072064] [django.request:152] [base:get_response] [WARNING]- Not Found: /blog/login/css/reglogin.css
2016-10-11 15:40:33,637 [Thread-17:139863494072064] [django.request:124] [exception:handle_uncaught_exception] [ERROR]- Internal Server Error: /blog/reg/
Traceback (most recent call last):
  File "/home/lgy/project/dj/env_2.7/local/lib/python2.7/site-packages/django/core/handlers/exception.py", line 39, in inner
    response = get_response(request)
  File "/home/lgy/project/dj/env_2.7/local/lib/python2.7/site-packages/django/core/handlers/base.py", line 198, in _get_response
    "returned None instead." % (callback.__module__, view_name)
ValueError: The view blog.views.reg didn't return an HttpResponse object. It returned None instead.
2016-10-11 15:40:38,650 [Thread-19:139863494072064] [django.request:152] [base:get_response] [WARNING]- Not Found: /blog/login/css/reglogin.css
2016-10-11 15:44:54,759 [Thread-3:140282892908288] [django.request:152] [base:get_response] [WARNING]- Not Found: /blog/login/css/reglogin.css
2016-10-14 02:34:46,748 [Thread-25:140489599465216] [django.request:152] [base:get_response] [WARNING]- Not Found: /favicon.ico
2016-10-24 07:10:38,973 [Thread-25:140484320147200] [django.request:152] [base:get_response] [WARNING]- Not Found: /favicon.ico
2016-10-24 07:10:39,035 [Thread-26:140484320147200] [django.request:152] [base:get_response] [WARNING]- Not Found: /favicon.ico
